<?xml version="1.0" encoding="utf-8"?>
<!-- This URDF was automatically created by SolidWorks to URDF Exporter! Originally created by Stephen Brawner (brawner@gmail.com) 
     Commit Version: 1.6.0-4-g7f85cfe  Build Version: 1.6.7995.38578
     For more information, please see http://wiki.ros.org/sw_urdf_exporter -->
<robot
  name="urc_gazebo">
  <link
    name="spine">
    <inertial>
      <origin
        xyz="-4.981E-05 -0.18559 -1.5877E-05"
        rpy="0 0 0" />
      <mass
        value="0.46585" />
      <inertia
        ixx="0.0042641"
        ixy="-9.1008E-09"
        ixz="3.5574E-07"
        iyy="0.00019731"
        iyz="4.925E-07"
        izz="0.0042645" />
    </inertial>
    <visual>
      <origin
        xyz="0 0 0"
        rpy="0 0 0" />
      <geometry>
        <mesh
          filename="$(find urc_gazebo)/meshes/spine.STL" />
      </geometry>
      <material
        name="">
        <color
          rgba="0.75294 0.75294 0.75294 1" />
      </material>
    </visual>
    <collision>
      <origin
        xyz="0 0 0"
        rpy="0 0 0" />
      <geometry>
        <mesh
          filename="$(find urc_gazebo)/meshes/spine.STL" />
      </geometry>
    </collision>
  </link>
  <link
    name="shoulder">
    <inertial>
      <origin
        xyz="0.062746 0.059252 -0.070221"
        rpy="0 0 0" />
      <mass
        value="1.3994" />
      <inertia
        ixx="0.002171"
        ixy="2.6981E-07"
        ixz="-2.0343E-07"
        iyy="0.0020295"
        iyz="-3.0183E-06"
        izz="0.0010438" />
    </inertial>
    <visual>
      <origin
        xyz="0 0 0"
        rpy="0 0 0" />
      <geometry>
        <mesh
          filename="$(find urc_gazebo)/meshes/shoulder.STL" />
      </geometry>
      <material
        name="">
        <color
          rgba="0.75294 0.75294 0.75294 1" />
      </material>
    </visual>
    <collision>
      <origin
        xyz="0 0 0"
        rpy="0 0 0" />
      <geometry>
        <mesh
          filename="$(find urc_gazebo)/meshes/shoulder.STL" />
      </geometry>
    </collision>
  </link>
  <joint
    name="shoulder_swivel"
    type="continuous">
    <origin
      xyz="0 0 0"
      rpy="1.5708 0 1.5708" />
    <parent
      link="spine" />
    <child
      link="shoulder" />
    <axis
      xyz="0 1 0" />
  </joint>
  <link
    name="bicep">
    <inertial>
      <origin
        xyz="-6.9389E-17 0.1747 1.9443E-05"
        rpy="0 0 0" />
      <mass
        value="0.2095" />
      <inertia
        ixx="0.0022797"
        ixy="-1.6687E-19"
        ixz="8.9374E-22"
        iyy="2.5264E-05"
        iyz="-1.0238E-18"
        izz="0.0022782" />
    </inertial>
    <visual>
      <origin
        xyz="0 0 0"
        rpy="0 0 0" />
      <geometry>
        <mesh
          filename="$(find urc_gazebo)/meshes/bicep.STL" />
      </geometry>
      <material
        name="">
        <color
          rgba="0.75294 0.75294 0.75294 1" />
      </material>
    </visual>
    <collision>
      <origin
        xyz="0 0 0"
        rpy="0 0 0" />
      <geometry>
        <mesh
          filename="$(find urc_gazebo)/meshes/bicep.STL" />
      </geometry>
    </collision>
  </link>
  <joint
    name="shoulder_hinge"
    type="continuous">
    <origin
      xyz="0 0.041262 0.046323"
      rpy="1.5708 -0.7854 -1.5708" />
    <parent
      link="shoulder" />
    <child
      link="bicep" />
    <axis
      xyz="0 0 1" />
  </joint>
  <link
    name="elbow">
    <inertial>
      <origin
        xyz="0.054749 0.11369 -0.026926"
        rpy="0 0 0" />
      <mass
        value="1.6005" />
      <inertia
        ixx="0.0023592"
        ixy="6.1347E-07"
        ixz="-6.8649E-07"
        iyy="0.0009948"
        iyz="-3.3055E-06"
        izz="0.0023065" />
    </inertial>
    <visual>
      <origin
        xyz="0 0 0"
        rpy="0 0 0" />
      <geometry>
        <mesh
          filename="$(find urc_gazebo)/meshes/elbow.STL" />
      </geometry>
      <material
        name="">
        <color
          rgba="0.75294 0.75294 0.75294 1" />
      </material>
    </visual>
    <collision>
      <origin
        xyz="0 0 0"
        rpy="0 0 0" />
      <geometry>
        <mesh
          filename="$(find urc_gazebo)/meshes/elbow.STL" />
      </geometry>
    </collision>
  </link>
  <joint
    name="elbow_hinge"
    type="continuous">
    <origin
      xyz="0 0.34925 0"
      rpy="0.7854 -1.5708 0" />
    <parent
      link="bicep" />
    <child
      link="elbow" />
    <axis
      xyz="1 0 0" />
  </joint>
  <link
    name="forearm">
    <inertial>
      <origin
        xyz="-9.7973E-05 -0.18274 0.00011875"
        rpy="0 0 0" />
      <mass
        value="0.1999" />
      <inertia
        ixx="0.00091726"
        ixy="-1.2951E-11"
        ixz="-8.6387E-09"
        iyy="0.0001085"
        iyz="1.3448E-11"
        izz="0.00090695" />
    </inertial>
    <visual>
      <origin
        xyz="0 0 0"
        rpy="0 0 0" />
      <geometry>
        <mesh
          filename="$(find urc_gazebo)/meshes/forearm.STL" />
      </geometry>
      <material
        name="">
        <color
          rgba="0.75294 0.75294 0.75294 1" />
      </material>
    </visual>
    <collision>
      <origin
        xyz="0 0 0"
        rpy="0 0 0" />
      <geometry>
        <mesh
          filename="$(find urc_gazebo)/meshes/forearm.STL" />
      </geometry>
    </collision>
  </link>
  <joint
    name="elbow_swivel"
    type="continuous">
    <origin
      xyz="0 -0.039571 -0.046323"
      rpy="3.1416 -1.5708 0" />
    <parent
      link="elbow" />
    <child
      link="forearm" />
    <axis
      xyz="0 1 0" />
  </joint>
  <link
    name="wrist">
    <inertial>
      <origin
        xyz="0.044478 0.083435 0.0011285"
        rpy="0 0 0" />
      <mass
        value="1.0055" />
      <inertia
        ixx="0.00083232"
        ixy="-4.6958E-07"
        ixz="-7.555E-07"
        iyy="0.00045909"
        iyz="7.2562E-07"
        izz="0.00077038" />
    </inertial>
    <visual>
      <origin
        xyz="0 0 0"
        rpy="0 0 0" />
      <geometry>
        <mesh
          filename="$(find urc_gazebo)/meshes/wrist.STL" />
      </geometry>
      <material
        name="">
        <color
          rgba="0.75294 0.75294 0.75294 1" />
      </material>
    </visual>
    <collision>
      <origin
        xyz="0 0 0"
        rpy="0 0 0" />
      <geometry>
        <mesh
          filename="$(find urc_gazebo)/meshes/wrist.STL" />
      </geometry>
    </collision>
  </link>
  <joint
    name="wrist_hinge"
    type="continuous">
    <origin
      xyz="0 -0.35513 0"
      rpy="1.5708 0 3.1416" />
    <parent
      link="forearm" />
    <child
      link="wrist" />
    <axis
      xyz="1 0 0" />
  </joint>
  <link
    name="end_effector">
    <inertial>
      <origin
        xyz="-4.4613E-05 -9.546E-06 0.28129"
        rpy="0 0 0" />
      <mass
        value="1.0966" />
      <inertia
        ixx="0.0015896"
        ixy="3.5229E-08"
        ixz="-3.3168E-07"
        iyy="0.0021713"
        iyz="3.4335E-08"
        izz="0.00087277" />
    </inertial>
    <visual>
      <origin
        xyz="0 0 0"
        rpy="0 0 0" />
      <geometry>
        <mesh
          filename="$(find urc_gazebo)/meshes/end_effector.STL" />
      </geometry>
      <material
        name="">
        <color
          rgba="0.75294 0.75294 0.75294 1" />
      </material>
    </visual>
    <collision>
      <origin
        xyz="0 0 0"
        rpy="0 0 0" />
      <geometry>
        <mesh
          filename="$(find urc_gazebo)/meshes/end_effector.STL" />
      </geometry>
    </collision>
  </link>
  <joint
    name="wrist_swivel"
    type="continuous">
    <origin
      xyz="0 -0.039689 -0.034131"
      rpy="1.5708 0 0" />
    <parent
      link="wrist" />
    <child
      link="end_effector" />
    <axis
      xyz="0 0 1" />
  </joint>
</robot>
