<?xml version="1.0" encoding="utf-8"?>
<!-- This URDF was automatically created by SolidWorks to URDF Exporter! Originally created by Stephen Brawner (brawner@gmail.com) 
     Commit Version: 1.6.0-4-g7f85cfe  Build Version: 1.6.7995.38578
     For more information, please see http://wiki.ros.org/sw_urdf_exporter -->
<robot
  name="RoboArm">
  <link
    name="base_link">
    <inertial>
      <origin
        xyz="0 0 1"
        rpy="0 0 0" />
      <mass
        value="0.523" />
      <inertia
        ixx="0.010808"
        ixy="-4.4773E-13"
        ixz="-1.3408E-13"
        iyy="0.010807"
        iyz="-4.0161E-12"
        izz="0.00038179" />
    </inertial>
    <visual>
      <origin
        xyz="0 0 0"
        rpy="0 0 0" />
      <geometry>
        <mesh
          filename="$(find urc_gazebo)/urdf/meshes/base_link.STL" />
      </geometry>
      <material
        name="">
        <color
          rgba="0.89804 0.91765 0.92941 1" />
      </material>
    </visual>
    <collision>
      <origin
        xyz="0 0 0"
        rpy="0 0 0" />
      <geometry>
        <mesh
          filename="$(find urc_gazebo)/urdf/meshes/base_link.STL" />
      </geometry>
    </collision>
  </link>
  <link
    name="shoulder">
    <inertial>
      <origin
        xyz="-0.060475 -0.024617 0.04737"
        rpy="0 0 0" />
      <mass
        value="2.4696" />
      <inertia
        ixx="0.004235"
        ixy="-0.00032614"
        ixz="-1.9936E-06"
        iyy="0.0033183"
        iyz="-7.6883E-06"
        izz="0.0024937" />
    </inertial>
    <visual>
      <origin
        xyz="0 0 0"
        rpy="0 0 0" />
      <geometry>
        <mesh
          filename="$(find urc_gazebo)/urdf/meshes/shoulder.STL" />
      </geometry>
      <material
        name="">
        <color
          rgba="0.52941 0.54902 0.54902 1" />
      </material>
    </visual>
    <collision>
      <origin
        xyz="0 0 0"
        rpy="0 0 0" />
      <geometry>
        <mesh
          filename="$(find urc_gazebo)/urdf/meshes/shoulder.STL" />
      </geometry>
    </collision>
  </link>
  <joint
    name="shoulderjoint"
    type="continuous">
    <origin
      xyz="0 0 0"
      rpy="0 0 0" />
    <parent
      link="base_link" />
    <child
      link="shoulder" />
    <axis
      xyz="0 0 -1" />
  </joint>
  <link
    name="bicep">
    <inertial>
      <origin
        xyz="-0.033709 -0.019568 0.12482"
        rpy="0 0 0" />
      <mass
        value="1.1771" />
      <inertia
        ixx="0.0063226"
        ixy="6.5403E-05"
        ixz="0.00023509"
        iyy="0.0060381"
        iyz="-0.0015391"
        izz="0.0008012" />
    </inertial>
    <visual>
      <origin
        xyz="0 0 0"
        rpy="0 0 0" />
      <geometry>
        <mesh
          filename="$(find urc_gazebo)/urdf/meshes/bicep.STL" />
      </geometry>
      <material
        name="">
        <color
          rgba="0.89804 0.91765 0.92941 1" />
      </material>
    </visual>
    <collision>
      <origin
        xyz="0 0 0"
        rpy="0 0 0" />
      <geometry>
        <mesh
          filename="$(find urc_gazebo)/urdf/meshes/bicep.STL" />
      </geometry>
    </collision>
  </link>
  <joint
    name="bicepjoint"
    type="fixed"> <!-- should be continuous/revolute -->
    <origin
      xyz="0 0 0"
      rpy="-1.5708 0 -0.35187" />
    <parent
      link="shoulder" />
    <child
      link="bicep" />
    <axis
      xyz="0.9991 0 0.042395" />
  </joint>
  <link
    name="elbow">
    <inertial>
      <origin
        xyz="-0.2653 -0.067321 0.22406"
        rpy="0 0 0" />
      <mass
        value="2.3313" />
      <inertia
        ixx="0.0019882"
        ixy="-4.2108E-07"
        ixz="-0.00054904"
        iyy="0.0027669"
        iyz="5.8953E-07"
        izz="0.0022384" />
    </inertial>
    <visual>
      <origin
        xyz="0 0 0"
        rpy="0 0 0" />
      <geometry>
        <mesh
          filename="$(find urc_gazebo)/urdf/meshes/elbow.STL" />
      </geometry>
      <material
        name="">
        <color
          rgba="0.65098 0.61961 0.58824 1" />
      </material>
    </visual>
    <collision>
      <origin
        xyz="0 0 0"
        rpy="0 0 0" />
      <geometry>
        <mesh
          filename="$(find urc_gazebo)/urdf/meshes/elbow.STL" />
      </geometry>
    </collision>
  </link>
  <joint
    name="elbowjoint"
    type="fixed"> <!-- should be continuous/revolute -->
    <origin
      xyz="0 0 0"
      rpy="-0.11095 1.1779 1.4682" />
    <parent
      link="bicep" />
    <child
      link="elbow" />
    <axis
      xyz="0 1 0" />
  </joint>
  <link
    name="forearm">
    <inertial>
      <origin
        xyz="0.17797 0.046312 0.022682"
        rpy="0 0 0" />
      <mass
        value="1.1353" />
      <inertia
        ixx="0.00033576"
        ixy="2.1424E-06"
        ixz="-2.1741E-06"
        iyy="0.0036586"
        iyz="1.423E-05"
        izz="0.0036493" />
    </inertial>
    <visual>
      <origin
        xyz="0 0 0"
        rpy="0 0 0" />
      <geometry>
        <mesh
          filename="$(find urc_gazebo)/urdf/meshes/forearm.STL" />
      </geometry>
      <material
        name="">
        <color
          rgba="0.52941 0.54902 0.54902 1" />
      </material>
    </visual>
    <collision>
      <origin
        xyz="0 0 0"
        rpy="0 0 0" />
      <geometry>
        <mesh
          filename="$(find urc_gazebo)/urdf/meshes/forearm.STL" />
      </geometry>
    </collision>
  </link>
  <joint
    name="forearmjoint"
    type="fixed"> <!-- should be continuous/revolute -->
    <origin
      xyz="-0.53446 -0.022729 0.034943"
      rpy="-1.5708 -0.6694 0" />
    <parent
      link="elbow" />
    <child
      link="forearm" />
    <axis
      xyz="-1 0 0" />
  </joint>
  <link
    name="endeffector">
    <inertial>
      <origin
        xyz="-0.01361 -0.071267 0.47099"
        rpy="0 0 0" />
      <mass
        value="1.8205" />
      <inertia
        ixx="0.0013189"
        ixy="0.00012111"
        ixz="3.9102E-05"
        iyy="0.0011033"
        iyz="-8.5009E-05"
        izz="0.0012718" />
    </inertial>
    <visual>
      <origin
        xyz="0 0 0"
        rpy="0 0 0" />
      <geometry>
        <mesh
          filename="$(find urc_gazebo)/urdf/meshes/endeffector.STL" />
      </geometry>
      <material
        name="">
        <color
          rgba="0.89804 0.91765 0.92941 1" />
      </material>
    </visual>
    <collision>
      <origin
        xyz="0 0 0"
        rpy="0 0 0" />
      <geometry>
        <mesh
          filename="$(find urc_gazebo)/urdf/meshes/endeffector.STL" />
      </geometry>
    </collision>
  </link>
  <joint
    name="endeffectorjoint"
    type="fixed"> <!-- should be continuous/revolute --> 
    <origin
      xyz="0.33807 0.046323 0.048129"
      rpy="1.5708 1.0472 -1.5708" />
    <parent
      link="forearm" />
    <child
      link="endeffector" />
    <axis
      xyz="0.9117 0.41086 0" />
  </joint>
  <link
    name="clawbase">
    <inertial>
      <origin
        xyz="-0.041874 0.0097839 -0.13314"
        rpy="0 0 0" />
      <mass
        value="1.5984" />
      <inertia
        ixx="0.0016783"
        ixy="-0.00024724"
        ixz="-1.0878E-06"
        iyy="0.0013472"
        iyz="-7.1138E-08"
        izz="0.00087963" />
    </inertial>
    <visual>
      <origin
        xyz="0 0 0"
        rpy="0 0 0" />
      <geometry>
        <mesh
          filename="$(find urc_gazebo)/urdf/meshes/clawbase.STL" />
      </geometry>
      <material
        name="">
        <color
          rgba="0.2 0.4 0.69804 1" />
      </material>
    </visual>
    <collision>
      <origin
        xyz="0 0 0"
        rpy="0 0 0" />
      <geometry>
        <mesh
          filename="$(find urc_gazebo)/urdf/meshes/clawbase.STL" />
      </geometry>
    </collision>
  </link>
  <joint
    name="clawbasejoint"
    type="continuous">
    <origin
      xyz="0.059627 0.0042582 0.43251"
      rpy="1.9117 0 0.4234" />
    <parent
      link="endeffector" />
    <child
      link="clawbase" />
    <axis
      xyz="0 0 1" />
  </joint>
  <link
    name="claw">
    <inertial>
      <origin
        xyz="-4.5879E-06 0.32283 -3.998E-05"
        rpy="0 0 0" />
      <mass
        value="0.73761" />
      <inertia
        ixx="0.0013658"
        ixy="-1.9078E-09"
        ixz="-1.0142E-05"
        iyy="0.00032501"
        iyz="2.0092E-10"
        izz="0.0012704" />
    </inertial>
    <visual>
      <origin
        xyz="0 0 0"
        rpy="0 0 0" />
      <geometry>
        <mesh
          filename="$(find urc_gazebo)/urdf/meshes/claw.STL" />
      </geometry>
      <material
        name="">
        <color
          rgba="1 1 1 1" />
      </material>
    </visual>
    <collision>
      <origin
        xyz="0 0 0"
        rpy="0 0 0" />
      <geometry>
        <mesh
          filename="$(find urc_gazebo)/urdf/meshes/claw.STL" />
      </geometry>
    </collision>
  </link>
  <joint
    name="clawjoint"
    type="prismatic">
    <origin
      xyz="-0.041275 0.0094698 -0.10395"
      rpy="-1.5708 0 -0.38633" />
    <parent
      link="clawbase" />
    <child
      link="claw" />
    <axis
      xyz="0 1 0" />
    <limit
      lower="0"
      upper="0"
      effort="0"
      velocity="0" />
  </joint>
</robot>
