<?xml version="1.0" encoding="utf-8" ?>
<!-- This URDF was automatically created by SolidWorks to URDF Exporter! Originally created by Stephen Brawner (brawner@gmail.com) 
     Commit Version: 1.6.0-4-g7f85cfe  Build Version: 1.6.7995.38578
     For more information, please see http://wiki.ros.org/sw_urdf_exporter -->
<robot name="RoboticArm">
    <link name="arm_base_link">
        <inertial>
            <origin xyz="0 0 0.6" rpy="0 0 0" />
            <mass value="0.523" />
            <inertia ixx="0.010808" ixy="-4.4773E-13" ixz="-1.3408E-13" iyy="0.010807" iyz="-4.0161E-12" izz="0.00038179" />
        </inertial>
        <visual>
            <origin xyz="0 0 0" rpy="0 0 0" />
            <geometry>
                <mesh filename="$(find urc_gazebo)/urdf/meshes/base_link.STL" />
            </geometry>
            <material name="">
                <color rgba="0.89804 0.91765 0.92941 1" />
            </material>
        </visual>
        <collision>
            <origin xyz="0 0 0" rpy="0 0 0" />
            <geometry>
                <mesh filename="$(find urc_gazebo)/urdf/meshes/base_link.STL" />
            </geometry>
        </collision>
    </link>
    <joint name="arm_joint" type="fixed">
      <origin xyz="0 0 0.6"/>
      <parent link="base_link"/>
      <child link="arm_base_link"/>
    </joint>
    <link name="shoulder">
        <inertial>
            <origin xyz="-0.057629 -0.030685 0.04737" rpy="0 0 0" />
            <mass value="2.4696" />
            <inertia ixx="0.0042918" ixy="-0.00022593" ixz="-1.5804E-06" iyy="0.0032615" iyz="-7.8719E-06" izz="0.0024937" />
        </inertial>
        <visual>
            <origin xyz="0 0 0" rpy="0 0 0" />
            <geometry>
                <mesh filename="$(find urc_gazebo)/urdf/meshes/shoulder.STL" />
            </geometry>
            <material name="">
                <color rgba="0.52941 0.54902 0.54902 1" />
            </material>
        </visual>
        <collision>
            <origin xyz="0 0 0" rpy="0 0 0" />
            <geometry>
                <mesh filename="$(find urc_gazebo)/urdf/meshes/shoulder.STL" />
            </geometry>
        </collision>
    </link>
    <joint name="shoulderjoint" type="continuous">
        <origin xyz="0 0 0" rpy="0 0 0" />
        <parent link="arm_base_link" />
        <child link="shoulder" />
        <axis xyz="0 0 -1" />
    </joint>
    
 
    <ros2_control name="GazeboSystem" type="system">
    <hardware>
      <plugin>gazebo_ros2_control/GazeboSystem</plugin>
    </hardware>   
      <joint name ="shoulderjoint">
        <command_interface name="position" />
        <state_interface name="position">
          <param name="initial_value">0.0</param>
        </state_interface>
        <state_interface name="velocity"/>
      </joint>   
    </ros2_control>
    
    
  <gazebo>
    <plugin filename="libgazebo_ros2_control.so" name ="gazebo_ros2_control">
      <!-- problematic: yaml parse crashes simulation-->
      <parameters>$(find urc_gazebo)/urdf/config/RoboticArm_params.yaml</parameters>
    </plugin>
  </gazebo>
</robot>
