<?xml version="1.0" encoding="utf-8"?>
<!-- This URDF was automatically created by SolidWorks to URDF Exporter! Originally created by Stephen Brawner (brawner@gmail.com) 
     Commit Version: 1.6.0-4-g7f85cfe  Build Version: 1.6.7995.38578
     For more information, please see http://wiki.ros.org/sw_urdf_exporter -->
<robot
  name="RoboticArm">
  <link
    name="base_link">
    <inertial>
      <origin
        xyz="0 0 0"
        rpy="0 0 0" />
      <mass
        value="0.523" />
      <inertia
        ixx="0.010808"
        ixy="-4.4773E-13"
        ixz="-1.3408E-13"
        iyy="0.010807"
        iyz="-4.0161E-12"
        izz="0.00038179" />
    </inertial>
    <visual>
      <origin
        xyz="0 0 0"
        rpy="0 0 0" />
      <geometry>
        <mesh
          filename="$(find urc_gazebo)/urdf/meshes/base_link.STL" />
      </geometry>
      <material
        name="">
        <color
          rgba="0.89804 0.91765 0.92941 1" />
      </material>
    </visual>
    <collision>
      <origin
        xyz="0 0 0"
        rpy="0 0 0" />
      <geometry>
        <mesh
          filename="$(find urc_gazebo)/urdf/meshes/base_link.STL" />
      </geometry>
    </collision>
  </link>
  <link
    name="shoulder">
    <inertial>
      <origin
        xyz="-0.057516 -0.030895 0.04737"
        rpy="0 0 0" />
      <mass
        value="2.4696" />
      <inertia
        ixx="0.0042934"
        ixy="-0.00022215"
        ixz="-1.5653E-06"
        iyy="0.0032599"
        iyz="-7.8777E-06"
        izz="0.0024937" />
    </inertial>
    <visual>
      <origin
        xyz="0 0 0"
        rpy="0 0 0" />
      <geometry>
        <mesh
          filename="$(find urc_gazebo)/urdf/meshes/shoulder.STL" />
      </geometry>
      <material
        name="">
        <color
          rgba="0.52941 0.54902 0.54902 1" />
      </material>
    </visual>
    <collision>
      <origin
        xyz="0 0 0"
        rpy="0 0 0" />
      <geometry>
        <mesh
          filename="$(find urc_gazebo)/urdf/meshes/shoulder.STL" />
      </geometry>
    </collision>
  </link>
  <joint
    name="shoulderjoint"
    type="continuous">
    <origin
      xyz="0 0 0"
      rpy="0 0 0" />
    <parent
      link="base_link" />
    <child
      link="shoulder" />
    <axis
      xyz="0 0 -1" />
  </joint>
  <link
    name="bicep">
    <inertial>
      <origin
        xyz="0.088588 -0.029308 0.077346"
        rpy="0 0 0" />
      <mass
        value="1.1771" />
      <inertia
        ixx="0.0063326"
        ixy="9.2675E-08"
        ixz="-3.6969E-07"
        iyy="0.0056923"
        iyz="0.0020171"
        izz="0.001137" />
    </inertial>
    <visual>
      <origin
        xyz="0 0 0"
        rpy="0 0 0" />
      <geometry>
        <mesh
          filename="$(find urc_gazebo)/urdf/meshes/bicep.STL" />
      </geometry>
      <material
        name="">
        <color
          rgba="0.89804 0.91765 0.92941 1" />
      </material>
    </visual>
    <collision>
      <origin
        xyz="0 0 0"
        rpy="0 0 0" />
      <geometry>
        <mesh
          filename="$(find urc_gazebo)/urdf/meshes/bicep.STL" />
      </geometry>
    </collision>
  </link>
  <joint
    name="bicepjoint"
    type="continuous">
    <origin
      xyz="0.068308 0.033227 0.041262"
      rpy="1.5708 0 2.9385" />
    <parent
      link="shoulder" />
    <child
      link="bicep" />
    <axis
      xyz="-1 0 0" />
  </joint>
  <link
    name="elbow">
    <inertial>
      <origin
        xyz="-0.12752 -0.060357 -0.047394"
        rpy="0 0 0" />
      <mass
        value="2.3313" />
      <inertia
        ixx="0.0027669"
        ixy="-3.2722E-07"
        ixz="6.4659E-07"
        iyy="0.0017335"
        iyz="-0.00041577"
        izz="0.0024931" />
    </inertial>
    <visual>
      <origin
        xyz="0 0 0"
        rpy="0 0 0" />
      <geometry>
        <mesh
          filename="$(find urc_gazebo)/urdf/meshes/elbow.STL" />
      </geometry>
      <material
        name="">
        <color
          rgba="0.65098 0.61961 0.58824 1" />
      </material>
    </visual>
    <collision>
      <origin
        xyz="0 0 0"
        rpy="0 0 0" />
      <geometry>
        <mesh
          filename="$(find urc_gazebo)/urdf/meshes/elbow.STL" />
      </geometry>
    </collision>
  </link>
  <joint
    name="elbowjoint"
    type="continuous">
    <origin
      xyz="0.1204 -0.12377 0.32658"
      rpy="0 0 0" />
    <parent
      link="bicep" />
    <child
      link="elbow" />
    <axis
      xyz="1 0 0" />
  </joint>
  <link
    name="forearm">
    <inertial>
      <origin
        xyz="-0.31229 -9.7716E-06 -5.9818E-05"
        rpy="0 0 0" />
      <mass
        value="1.1353" />
      <inertia
        ixx="0.00033576"
        ixy="2.1424E-06"
        ixz="-2.1741E-06"
        iyy="0.0036528"
        iyz="1.5007E-05"
        izz="0.0036552" />
    </inertial>
    <visual>
      <origin
        xyz="0 0 0"
        rpy="0 0 0" />
      <geometry>
        <mesh
          filename="$(find urc_gazebo)/urdf/meshes/forearm.STL" />
      </geometry>
      <material
        name="">
        <color
          rgba="0.52941 0.54902 0.54902 1" />
      </material>
    </visual>
    <collision>
      <origin
        xyz="0 0 0"
        rpy="0 0 0" />
      <geometry>
        <mesh
          filename="$(find urc_gazebo)/urdf/meshes/forearm.STL" />
      </geometry>
    </collision>
  </link>
  <joint
    name="forearmjoint"
    type="continuous">
    <origin
      xyz="-0.060202 -0.19694 -0.1385"
      rpy="-1.5708 0.41929 -1.5708" />
    <parent
      link="elbow" />
    <child
      link="forearm" />
    <axis
      xyz="-1 0 0" />
  </joint>
  <link
    name="endeffector">
    <inertial>
      <origin
        xyz="0.095201 0.012411 -0.044729"
        rpy="0 0 0" />
      <mass
        value="2.2712" />
      <inertia
        ixx="0.0018657"
        ixy="-1.1142E-06"
        ixz="-3.2769E-07"
        iyy="0.0017275"
        iyz="0.00021458"
        izz="0.0011425" />
    </inertial>
    <visual>
      <origin
        xyz="0 0 0"
        rpy="0 0 0" />
      <geometry>
        <mesh
          filename="$(find urc_gazebo)/urdf/meshes/endeffector.STL" />
      </geometry>
      <material
        name="">
        <color
          rgba="0.89804 0.91765 0.92941 1" />
      </material>
    </visual>
    <collision>
      <origin
        xyz="0 0 0"
        rpy="0 0 0" />
      <geometry>
        <mesh
          filename="$(find urc_gazebo)/urdf/meshes/endeffector.STL" />
      </geometry>
    </collision>
  </link>
  <joint
    name="endeffectorjoint"
    type="continuous">
    <origin
      xyz="-0.63096 -0.034252 -0.036275"
      rpy="-0.3134 -0.81406 1.5708" />
    <parent
      link="forearm" />
    <child
      link="endeffector" />
    <axis
      xyz="-1 0 0" />
  </joint>
  <link
    name="clawbase">
    <inertial>
      <origin
        xyz="0.42633 -0.00068376 -0.00063636"
        rpy="0 0 0" />
      <mass
        value="1.1594" />
      <inertia
        ixx="0.00082286"
        ixy="8.0907E-07"
        ixz="3.1937E-07"
        iyy="0.0010464"
        iyz="0.00029681"
        izz="0.0010012" />
    </inertial>
    <visual>
      <origin
        xyz="0 0 0"
        rpy="0 0 0" />
      <geometry>
        <mesh
          filename="$(find urc_gazebo)/urdf/meshes/clawbase.STL" />
      </geometry>
      <material
        name="">
        <color
          rgba="0.2 0.4 0.69804 1" />
      </material>
    </visual>
    <collision>
      <origin
        xyz="0 0 0"
        rpy="0 0 0" />
      <geometry>
        <mesh
          filename="$(find urc_gazebo)/urdf/meshes/clawbase.STL" />
      </geometry>
    </collision>
  </link>
  <joint
    name="clawbasejoint"
    type="continuous">
    <origin
      xyz="0.049891 0.041686 -0.2346"
      rpy="1.2733 -1.2512 -1.5708" />
    <parent
      link="endeffector" />
    <child
      link="clawbase" />
    <axis
      xyz="1 0 0" />
  </joint>
  <link
    name="claw">
    <inertial>
      <origin
        xyz="0.13526 -2.8019E-07 -2.5901E-07"
        rpy="0 0 0" />
      <mass
        value="0.73761" />
      <inertia
        ixx="0.00030508"
        ixy="-1.4067E-09"
        ixz="-1.3046E-09"
        iyy="0.001331"
        iyz="3.8687E-05"
        izz="0.0013251" />
    </inertial>
    <visual>
      <origin
        xyz="0 0 0"
        rpy="0 0 0" />
      <geometry>
        <mesh
          filename="$(find urc_gazebo)/urdf/meshes/claw.STL" />
      </geometry>
      <material
        name="">
        <color
          rgba="1 1 1 1" />
      </material>
    </visual>
    <collision>
      <origin
        xyz="0 0 0"
        rpy="0 0 0" />
      <geometry>
        <mesh
          filename="$(find urc_gazebo)/urdf/meshes/claw.STL" />
      </geometry>
    </collision>
  </link>
  <joint
    name="clawjoint"
    type="prismatic">
    <origin
      xyz="0.51169 -2.7356E-05 2.9513E-05"
      rpy="0 0 0" />
    <parent
      link="clawbase" />
    <child
      link="claw" />
    <axis
      xyz="1 0 0" />
    <limit
      lower="0"
      upper="0"
      effort="0"
      velocity="0" />
  </joint>
</robot>
