<?xml version="1.0" encoding="utf-8"?>
<!-- This URDF was automatically created by SolidWorks to URDF Exporter! Originally created by Stephen Brawner (brawner@gmail.com) 
     Commit Version: 1.6.0-4-g7f85cfe  Build Version: 1.6.7995.38578
     For more information, please see http://wiki.ros.org/sw_urdf_exporter -->
<robot
  name="WalliiArm">
  <link name="world"/>
  <link
    name="base_link">
    <inertial>
      <origin
        xyz="-0.00012842 -6.9829E-05 -0.23247"
        rpy="0 0 0" />
      <mass
        value="0.523" />
      <inertia
        ixx="0.010808"
        ixy="-4.4773E-13"
        ixz="-1.3408E-13"
        iyy="0.010807"
        iyz="-4.0161E-12"
        izz="0.00038179" />
    </inertial>
    <visual>
      <origin
        xyz="0 0 0"
        rpy="0 0 0" />
      <geometry>
        <mesh
          filename="$(find urc_gazebo)/urdf/meshes/base_link.STL" />
      </geometry>
      <material
        name="">
        <color
          rgba="0.89804 0.91765 0.92941 1" />
      </material>
    </visual>
    <collision>
      <origin
        xyz="0 0 0"
        rpy="0 0 0" />
      <geometry>
        <mesh
          filename="$(find urc_gazebo)/urdf/meshes/base_link.STL" />
      </geometry>
    </collision>
  </link>
  <joint name="world_to_base" type="fixed">
    <origin rpy="0 0 0" xyz="0 0 1"/>
    <parent link="world"/>
    <child link="base_link"/>
  </joint>
  <link
    name="shoulder">
    <inertial>
      <origin
        xyz="0.052564 -0.02513 0.046902"
        rpy="0 0 0" />
      <mass
        value="2.6747" />
      <inertia
        ixx="0.0035378"
        ixy="-0.00047941"
        ixz="4.1985E-06"
        iyy="0.0042134"
        iyz="-2.3786E-06"
        izz="0.002566" />
    </inertial>
    <visual>
      <origin
        xyz="0 0 0"
        rpy="0 0 0" />
      <geometry>
        <mesh
          filename="$(find urc_gazebo)/urdf/meshes/shoulder.STL" />
      </geometry>
      <material
        name="">
        <color
          rgba="0.52941 0.54902 0.54902 1" />
      </material>
    </visual>
    <collision>
      <origin
        xyz="0 0 0"
        rpy="0 0 0" />
      <geometry>
        <mesh
          filename="$(find urc_gazebo)/urdf/meshes/shoulder.STL" />
      </geometry>
    </collision>
  </link>
  <joint
    name="shoulderjoint"
    type="continuous">
    <origin
      xyz="0 0 0"
      rpy="0 0 0" />
    <parent
      link="base_link" />
    <child
      link="shoulder" />
    <axis
      xyz="0 0 -1" />
    <limit
      lower="-3.14"
      upper="3.14"
      effort="0"
      velocity="0" />
  </joint>
  <link
    name="bicep">
    <inertial>
      <origin
        xyz="0.083844 -0.0017192 0.12224"
        rpy="0 0 0" />
      <mass
        value="1.3821" />
      <inertia
        ixx="0.0064561"
        ixy="9.1648E-08"
        ixz="-3.9088E-07"
        iyy="0.006528"
        iyz="8.4887E-05"
        izz="0.00044807" />
    </inertial>
    <visual>
      <origin
        xyz="0 0 0"
        rpy="0 0 0" />
      <geometry>
        <mesh
          filename="$(find urc_gazebo)/urdf/meshes/bicep.STL" />
      </geometry>
      <material
        name="">
        <color
          rgba="0.89804 0.91765 0.92941 1" />
      </material>
    </visual>
    <collision>
      <origin
        xyz="0 0 0"
        rpy="0 0 0" />
      <geometry>
        <mesh
          filename="$(find urc_gazebo)/urdf/meshes/bicep.STL" />
      </geometry>
    </collision>
  </link>
  <joint
    name="bicepjoint"
    type="continuous">
    <origin
      xyz="-0.06881 0.032176 0.041262"
      rpy="1.5708 0 -1.0932" />
    <parent
      link="shoulder" />
    <child
      link="bicep" />
    <axis
      xyz="-1 0 0" />
    <limit
      lower="-1.57"
      upper="1.57"
      effort="0"
      velocity="0" />
  </joint>

  
  
  
  
  
  
  <ros2_control name="GazeboSystem" type="system">
    <hardware>
      <plugin>gazebo_ros2_control/GazeboSystem</plugin>
    </hardware>
    <joint name ="arm_joint">
        <command_interface name="position" />
        <state_interface name="position">
          <param name="initial_value">0.0</param>
        </state_interface>
        <state_interface name="velocity"/>
      </joint>
      
      <joint name ="shoulderjoint">
        <command_interface name="position" />
        <state_interface name="position">
          <param name="initial_value">0.0</param>
        </state_interface>
        <state_interface name="velocity"/>
      </joint>
      
      <joint name ="bicepjoint">
        <command_interface name="position" />
        <state_interface name="position">
          <param name="initial_value">0.0</param>
        </state_interface>
        <state_interface name="velocity"/>
      </joint>

      
      
      
       
      
    </ros2_control>
  <gazebo>
    <plugin name ="gazebo_ros2_control" filename="libgazebo_ros2_control.so">
      <!-- problematic: yaml parse crashes simulation-->
      <parameters>$(find urc_gazebo)/urdf/config/RoboticArm_params.yaml</parameters>
    </plugin>
  </gazebo>
  
</robot>
