<?xml version="1.0" encoding="utf-8"?>
<!-- This URDF was automatically created by SolidWorks to URDF Exporter! Originally created by Stephen Brawner (brawner@gmail.com) 
     Commit Version: 1.6.0-4-g7f85cfe  Build Version: 1.6.7995.38578
     For more information, please see http://wiki.ros.org/sw_urdf_exporter -->
<robot
  name="WalliiArmV1">
  <link name="world"/>
  <link
    name="base_link">
    <inertial>
      <origin
        xyz="-0.00012842 -6.9829E-05 -0.23247"
        rpy="0 0 0" />
      <mass
        value="0.523" />
      <inertia
        ixx="0.010808"
        ixy="-4.4773E-13"
        ixz="-1.3408E-13"
        iyy="0.010807"
        iyz="-4.0161E-12"
        izz="0.00038179" />
    </inertial>
    <visual>
      <origin
        xyz="0 0 0"
        rpy="0 0 0" />
      <geometry>
        <mesh
          filename="$(find urc_gazebo)/urdf/meshes/base_link.STL" />
      </geometry>
      <material
        name="">
        <color
          rgba="0.89804 0.91765 0.92941 1" />
      </material>
    </visual>
    <collision>
      <origin
        xyz="0 0 0"
        rpy="0 0 0" />
      <geometry>
        <mesh
          filename="$(find urc_gazebo)/urdf/meshes/base_link.STL" />
      </geometry>
    </collision>
  </link>
  <joint name="world_to_base" type="fixed">
    <origin rpy="0 0 0" xyz="0 0 1"/>
    <parent link="world"/>
    <child link="base_link"/>
  </joint>
  <link
    name="shoulder">
    <inertial>
      <origin
        xyz="0.060206 -0.025185 0.04737"
        rpy="0 0 0" />
      <mass
        value="2.4696" />
      <inertia
        ixx="0.003453"
        ixy="-0.00045936"
        ixz="4.185E-06"
        iyy="0.0041003"
        iyz="-2.3843E-06"
        izz="0.0024937" />
    </inertial>
    <visual>
      <origin
        xyz="0 0 0"
        rpy="0 0 0" />
      <geometry>
        <mesh
          filename="$(find urc_gazebo)/urdf/meshes/shoulder.STL" />
      </geometry>
      <material
        name="">
        <color
          rgba="0.52941 0.54902 0.54902 1" />
      </material>
    </visual>
    <collision>
      <origin
        xyz="0 0 0"
        rpy="0 0 0" />
      <geometry>
        <mesh
          filename="$(find urc_gazebo)/urdf/meshes/shoulder.STL" />
      </geometry>
    </collision>
  </link>
  <joint
    name="shoulderjoint"
    type="continuous">
    <origin
      xyz="0 0 0"
      rpy="0 0 0" />
    <parent
      link="base_link" />
    <child
      link="shoulder" />
    <axis
      xyz="0 0 -1" />
    <limit
      lower="-3.14"
      upper="3.14"
      effort="0"
      velocity="0" />
  </joint>
  <link
    name="bicep">
    <inertial>
      <origin
        xyz="0.088588 -0.0011692 0.082703"
        rpy="0 0 0" />
      <mass
        value="1.1771" />
      <inertia
        ixx="0.0063326"
        ixy="9.2682E-08"
        ixz="-3.6973E-07"
        iyy="0.0064557"
        iyz="8.4885E-05"
        izz="0.00037364" />
    </inertial>
    <visual>
      <origin
        xyz="0 0 0"
        rpy="0 0 0" />
      <geometry>
        <mesh
          filename="$(find urc_gazebo)/urdf/meshes/bicep.STL" />
      </geometry>
      <material
        name="">
        <color
          rgba="0.89804 0.91765 0.92941 1" />
      </material>
    </visual>
    <collision>
      <origin
        xyz="0 0 0"
        rpy="0 0 0" />
      <geometry>
        <mesh
          filename="$(find urc_gazebo)/urdf/meshes/bicep.STL" />
      </geometry>
    </collision>
  </link>
  <joint
    name="bicepjoint"
    type="continuous">
    <origin
      xyz="-0.06881 0.032176 0.041262"
      rpy="1.5708 0 -1.0932" />
    <parent
      link="shoulder" />
    <child
      link="bicep" />
    <axis
      xyz="-1 0 0" />
    <limit
      lower="-1.57"
      upper="1.57"
      effort="0"
      velocity="0" />
  </joint>
  <link
    name="elbow">
    <inertial>
      <origin
        xyz="-0.12752 0.074311 0.019159"
        rpy="0 0 0" />
      <mass
        value="2.3313" />
      <inertia
        ixx="0.0027669"
        ixy="3.9904E-08"
        ixz="-7.2338E-07"
        iyy="0.0015502"
        iyz="-2.2101E-06"
        izz="0.0026764" />
    </inertial>
    <visual>
      <origin
        xyz="0 0 0"
        rpy="0 0 0" />
      <geometry>
        <mesh
          filename="$(find urc_gazebo)/urdf/meshes/elbow.STL" />
      </geometry>
      <material
        name="">
        <color
          rgba="0.65098 0.61961 0.58824 1" />
      </material>
    </visual>
    <collision>
      <origin
        xyz="0 0 0"
        rpy="0 0 0" />
      <geometry>
        <mesh
          filename="$(find urc_gazebo)/urdf/meshes/elbow.STL" />
      </geometry>
    </collision>
  </link>
  <joint
    name="elbowjoint"
    type="continuous">
    <origin
      xyz="0.1204 -0.0048791 0.34922"
      rpy="0 0 0" />
    <parent
      link="bicep" />
    <child
      link="elbow" />
    <axis
      xyz="1 0 0" />
    <limit
      lower="-1.57"
      upper="1.57"
      effort="0"
      velocity="0" />
  </joint>
  <link
    name="forearm">
    <inertial>
      <origin
        xyz="-0.31404 -4.4479E-05 6.6393E-06"
        rpy="0 0 0" />
      <mass
        value="1.1432" />
      <inertia
        ixx="0.00033756"
        ixy="-2.1425E-06"
        ixz="2.1741E-06"
        iyy="0.003668"
        iyz="-6.3927E-06"
        izz="0.0036417" />
    </inertial>
    <visual>
      <origin
        xyz="0 0 0"
        rpy="0 0 0" />
      <geometry>
        <mesh
          filename="$(find urc_gazebo)/urdf/meshes/forearm.STL" />
      </geometry>
      <material
        name="">
        <color
          rgba="0.52941 0.54902 0.54902 1" />
      </material>
    </visual>
    <collision>
      <origin
        xyz="0 0 0"
        rpy="0 0 0" />
      <geometry>
        <mesh
          filename="$(find urc_gazebo)/urdf/meshes/forearm.STL" />
      </geometry>
    </collision>
  </link>
  <joint
    name="forearmjoint"
    type="fixed">
    <origin
      xyz="-0.060202 0.23598 0.047728"
      rpy="-1.5708 -0.0059508 1.5708" />
    <parent
      link="elbow" />
    <child
      link="forearm" />
    <axis
      xyz="-1 0 0" />
    <limit
      lower="-3.14"
      upper="3.14"
      effort="0"
      velocity="0" />
  </joint>
  <link
    name="endeffector">
    <inertial>
      <origin
        xyz="0.083403 -0.010272 0.0063622"
        rpy="0 0 0" />
      <mass
        value="3.0799" />
      <inertia
        ixx="0.002134"
        ixy="-7.9846E-08"
        ixz="5.1688E-08"
        iyy="0.0020547"
        iyz="-3.7816E-05"
        izz="0.0012986" />
    </inertial>
    <visual>
      <origin
        xyz="0 0 0"
        rpy="0 0 0" />
      <geometry>
        <mesh
          filename="$(find urc_gazebo)/urdf/meshes/endeffector.STL" />
      </geometry>
      <material
        name="">
        <color
          rgba="0.89804 0.91765 0.92941 1" />
      </material>
    </visual>
    <collision>
      <origin
        xyz="0 0 0"
        rpy="0 0 0" />
      <geometry>
        <mesh
          filename="$(find urc_gazebo)/urdf/meshes/endeffector.STL" />
      </geometry>
    </collision>
  </link>
  <joint
    name="endeffectorjoint"
    type="fixed">
    <origin
      xyz="-0.63096 0.048851 -0.010135"
      rpy="0.0012088 -0.20455 -1.5708" />
    <parent
      link="forearm" />
    <child
      link="endeffector" />
    <axis
      xyz="-1 0 0" />
    <limit
      lower="-1.57"
      upper="1.57"
      effort="0"
      velocity="0" />
  </joint>
  <link
    name="clawbase">
    <inertial>
      <origin
        xyz="0.42941 -0.00010015 0.00089893"
        rpy="0 0 0" />
      <mass
        value="1.2045" />
      <inertia
        ixx="0.00085053"
        ixy="-2.1113E-07"
        ixz="-8.5048E-07"
        iyy="0.00073796"
        iyz="-7.3164E-05"
        izz="0.0013396" />
    </inertial>
    <visual>
      <origin
        xyz="0 0 0"
        rpy="0 0 0" />
      <geometry>
        <mesh
          filename="$(find urc_gazebo)/urdf/meshes/clawbase.STL" />
      </geometry>
      <material
        name="">
        <color
          rgba="0.2 0.4 0.69804 1" />
      </material>
    </visual>
    <collision>
      <origin
        xyz="0 0 0"
        rpy="0 0 0" />
      <geometry>
        <mesh
          filename="$(find urc_gazebo)/urdf/meshes/clawbase.STL" />
      </geometry>
    </collision>
  </link>
  <joint
    name="clawbasejoint"
    type="fixed">
    <origin
      xyz="0.049886 -0.045035 -0.23398"
      rpy="-1.5644 -1.5244 1.5702" />
    <parent
      link="endeffector" />
    <child
      link="clawbase" />
    <axis
      xyz="1 0 0" />
    <limit
      lower="-3.14"
      upper="3.14"
      effort="0"
      velocity="0" />
  </joint>
  <link
    name="leftgripper">
    <inertial>
      <origin
        xyz="-0.0091314 0.018625 0.1054"
        rpy="0 0 0" />
      <mass
        value="0.34608" />
      <inertia
        ixx="0.00067001"
        ixy="-9.4915E-09"
        ixz="-6.1553E-08"
        iyy="0.00062684"
        iyz="-7.9107E-05"
        izz="0.00015499" />
    </inertial>
    <visual>
      <origin
        xyz="0 0 0"
        rpy="0 0 0" />
      <geometry>
        <mesh
          filename="$(find urc_gazebo)/urdf/meshes/leftgripper.STL" />
      </geometry>
      <material
        name="">
        <color
          rgba="0.89804 0.91765 0.92941 1" />
      </material>
    </visual>
    <collision>
      <origin
        xyz="0 0 0"
        rpy="0 0 0" />
      <geometry>
        <mesh
          filename="$(find urc_gazebo)/urdf/meshes/leftgripper.STL" />
      </geometry>
    </collision>
  </link>
  <joint
    name="leftgripperjoint"
    type="fixed">
    <origin
      xyz="0.55008 -0.078532 -0.01862"
      rpy="1.6163 1.4514 1.5696" />
    <parent
      link="clawbase" />
    <child
      link="leftgripper" />
    <axis
      xyz="1 0 0" />
  </joint>
  <link
    name="rightgripper">
    <inertial>
      <origin
        xyz="-0.012687 -0.0087023 0.10667"
        rpy="0 0 0" />
      <mass
        value="0.34608" />
      <inertia
        ixx="0.00067001"
        ixy="4.0022E-09"
        ixz="-6.2683E-08"
        iyy="0.00063743"
        iyz="3.3863E-05"
        izz="0.0001444" />
    </inertial>
    <visual>
      <origin
        xyz="0 0 0"
        rpy="0 0 0" />
      <geometry>
        <mesh
          filename="$(find urc_gazebo)/urdf/meshes/rightgripper.STL" />
      </geometry>
      <material
        name="">
        <color
          rgba="0.89804 0.91765 0.92941 1" />
      </material>
    </visual>
    <collision>
      <origin
        xyz="0 0 0"
        rpy="0 0 0" />
      <geometry>
        <mesh
          filename="$(find urc_gazebo)/urdf/meshes/rightgripper.STL" />
      </geometry>
    </collision>
  </link>
  <joint
    name="rightgripperjoint"
    type="fixed">
    <origin
      xyz="0.55008 0.081235 -0.0030407"
      rpy="1.6163 1.4514 1.5696" />
    <parent
      link="clawbase" />
    <child
      link="rightgripper" />
    <axis
      xyz="1 0 0" />
    <mimic
      joint="leftgripperjoint"
      multiplier="1"
      offset="0" />
  </joint>
  
  <ros2_control name="GazeboSystem" type="system">
    <hardware>
      <plugin>gazebo_ros2_control/GazeboSystem</plugin>
    </hardware>
    <joint name ="arm_joint">
        <command_interface name="position" />
        <state_interface name="position">
          <param name="initial_value">0.0</param>
        </state_interface>
        <state_interface name="velocity"/>
      </joint>
      
      <joint name ="shoulderjoint">
        <command_interface name="position" />
        <state_interface name="position">
          <param name="initial_value">0.0</param>
        </state_interface>
        <state_interface name="velocity"/>
      </joint>
      
      <joint name ="bicepjoint">
        <command_interface name="position" />
        <state_interface name="position">
          <param name="initial_value">0.0</param>
        </state_interface>
        <state_interface name="velocity"/>
      </joint>

      <joint name ="elbowjoint">
        <command_interface name="position" />
        <state_interface name="position">
          <param name="initial_value">0.0</param>
        </state_interface>
        <state_interface name="velocity"/>
      </joint>
	<joint name ="forearmjoint">
        <command_interface name="position" />
        <state_interface name="position">
          <param name="initial_value">0.0</param>
        </state_interface>
        <state_interface name="velocity"/>
      </joint>
	<joint name ="endeffectorjoint">
        <command_interface name="position" />
        <state_interface name="position">
          <param name="initial_value">0.0</param>
        </state_interface>
        <state_interface name="velocity"/>
      </joint>
      
      <joint name ="clawbasejoint">
        <command_interface name="position" />
        <state_interface name="position">
          <param name="initial_value">0.0</param>
        </state_interface>
        <state_interface name="velocity"/>
      </joint>
      
      <joint name ="leftgripperjoint">
        <command_interface name="position" />
        <state_interface name="position">
          <param name="initial_value">0.0</param>
        </state_interface>
        <state_interface name="velocity"/>
      </joint>
      
      <joint name ="rightgripperjoint">
        <command_interface name="position" />
        <state_interface name="position">
          <param name="initial_value">0.0</param>
        </state_interface>
        <state_interface name="velocity"/>
      </joint>  
    </ros2_control>

  <gazebo>
    <plugin name ="gazebo_ros2_control" filename="libgazebo_ros2_control.so">
      <!-- problematic: yaml parse crashes simulation-->
      <parameters>$(find urc_gazebo)/urdf/config/RoboticArm_params.yaml</parameters>
    </plugin>
  </gazebo>

</robot>
