<?xml version="1.0" encoding="utf-8"?>
<!-- This URDF was automatically created by SolidWorks to URDF Exporter! Originally created by Stephen Brawner (brawner@gmail.com) 
     Commit Version: 1.6.0-4-g7f85cfe  Build Version: 1.6.7995.38578
     For more information, please see http://wiki.ros.org/sw_urdf_exporter -->
<robot
  name="WalliiArmV3">
  <link
    name="arm_base_link">
    <inertial>
      <origin
        xyz="-8.1195E-05 0.025555 0.31181"
        rpy="0 0 0" />
      <mass
        value="0.56817" />
      <inertia
        ixx="0.010817"
        ixy="4.4773E-13"
        ixz="-4.0161E-12"
        iyy="0.010818"
        iyz="1.3408E-13"
        izz="0.00040167" />
    </inertial>
    <visual>
      <origin
        xyz="0 0 0"
        rpy="0 0 0" />
        <!-- $(find urc_gazebo) -->
        <!-- package://urc_gazebo -->
      <geometry>
        <mesh
          filename="package://urc_gazebo/urdf/meshes/base_link.STL" />
      </geometry>
      <material
        name="">
        <color
          rgba="0.75294 0.75294 0.75294 1" />
      </material>
    </visual>
    <collision>
      <origin
        xyz="0 0 0"
        rpy="0 0 0" />
      <geometry>
        <mesh
          filename="package://urc_gazebo/urdf/meshes/base_link_collision.STL" />
      </geometry>
    </collision>
  </link>
  <link
    name="shoulder">
    <inertial>
      <origin
        xyz="-0.04837 -0.018689 -0.068105"
        rpy="0 0 0" />
      <mass
        value="3.586" />
      <inertia
        ixx="0.004611"
        ixy="1.9578E-06"
        ixz="-4.7127E-06"
        iyy="0.0037191"
        iyz="-4.489E-06"
        izz="0.0029735" />
    </inertial>
    <visual>
      <origin
        xyz="0 0 0"
        rpy="0 0 0" />
      <geometry>
        <mesh
          filename="package://urc_gazebo/urdf/meshes/shoulder.STL" />
      </geometry>
      <material
        name="">
        <color
          rgba="0.75294 0.75294 0.75294 1" />
      </material>
    </visual>
    <collision>
      <origin
        xyz="0 0 0"
        rpy="0 0 0" />
      <geometry>
        <mesh
          filename="package://urc_gazebo/urdf/meshes/shoulder_collision.STL" />
      </geometry>
    </collision>
  </link>
  <joint
    name="shoulderjoint"
    type="continuous">
    <origin
      xyz="0.00028389 0.0254 0.62708"
      rpy="0 0 0" />
    <parent
      link="arm_base_link" />
    <child
      link="shoulder" />
    <axis
      xyz="0 0 -1" />
    <dynamics
      damping="60.0"
      friction="4.0" />
  </joint>
  <link
    name="bicep">
    <inertial>
      <origin
        xyz="0.12104 0.17465 -1.6653E-16"
        rpy="0 0 0" />
      <mass
        value="0.55725" />
      <inertia
        ixx="0.0061511"
        ixy="5.9124E-19"
        ixz="-2.0963E-21"
        iyy="6.7641E-05"
        iyz="-9.6466E-19"
        izz="0.0061546" />
    </inertial>
    <visual>
      <origin
        xyz="0 0 0"
        rpy="0 0 0" />
      <geometry>
        <mesh
          filename="package://urc_gazebo/urdf/meshes/bicep.STL" />
      </geometry>
      <material
        name="">
        <color
          rgba="0.75294 0.75294 0.75294 1" />
      </material>
    </visual>
    <collision>
      <origin
        xyz="0 0 0"
        rpy="0 0 0" />
      <geometry>
        <mesh
          filename="package://urc_gazebo/urdf/meshes/bicep_collision.STL" />
      </geometry>
    </collision>
  </link>
  <joint
    name="bicepjoint"
    type="revolute">
    <origin
      xyz="-0.12131 0.046323 -0.052413"
      rpy="0 0 0" />
    <parent
      link="shoulder" />
    <child
      link="bicep" />
    <axis
      xyz="1 0 0" />
    <limit
      lower="-1.57"
      upper="1.57"
      effort="0"
      velocity="0" />
    <dynamics
      damping="60.0"
      friction="4.0" />
  </joint>
  <link
    name="elbow">
    <inertial>
      <origin
        xyz="-0.06786 0.023863 0.062716"
        rpy="0 0 0" />
      <mass
        value="3.1709" />
      <inertia
        ixx="0.0039723"
        ixy="1.1762E-06"
        ixz="1.6958E-06"
        iyy="0.0039893"
        iyz="6.6104E-06"
        izz="0.0017383" />
    </inertial>
    <visual>
      <origin
        xyz="0 0 0"
        rpy="0 0 0" />
      <geometry>
        <mesh
          filename="package://urc_gazebo/urdf/meshes/elbow.STL" />
      </geometry>
      <material
        name="">
        <color
          rgba="0.75294 0.75294 0.75294 1" />
      </material>
    </visual>
    <collision>
      <origin
        xyz="0 0 0"
        rpy="0 0 0" />
      <geometry>
        <mesh
          filename="package://urc_gazebo/urdf/meshes/elbow_collision.STL" />
      </geometry>
    </collision>
  </link>
  <joint
    name="elbowjoint"
    type="revolute">
    <origin
      xyz="0.24206 0.34925 0"
      rpy="0 0 0" />
    <parent
      link="bicep" />
    <child
      link="elbow" />
    <axis
      xyz="1 0 0" />
    <limit
      lower="-1.57"
      upper="1.57"
      effort="0"
      velocity="0" />
    <dynamics
      damping="60.0"
      friction="4.0" />
  </joint>
  <link
    name="forearm">
    <inertial>
      <origin
        xyz="-0.00011067 9.3127E-05 -0.45483"
        rpy="0 0 0" />
      <mass
        value="0.53926" />
      <inertia
        ixx="0.0024603"
        ixy="-2.3325E-08"
        ixz="-3.8937E-11"
        iyy="0.0024892"
        iyz="3.5055E-11"
        izz="0.00029125" />
    </inertial>
    <visual>
      <origin
        xyz="0 0 0"
        rpy="0 0 0" />
      <geometry>
        <mesh
          filename="package://urc_gazebo/urdf/meshes/forearm.STL" />
      </geometry>
      <material
        name="">
        <color
          rgba="0.75294 0.75294 0.75294 1" />
      </material>
    </visual>
    <collision>
      <origin
        xyz="0 0 0"
        rpy="0 0 0" />
      <geometry>
        <mesh
          filename="package://urc_gazebo/urdf/meshes/forearm_collision.STL" />
      </geometry>
    </collision>
  </link>
  <joint
    name="forearmjoint"
    type="continuous">
    <origin
      xyz="-0.12103 0.046323 0.23626"
      rpy="0 0 0" />
    <parent
      link="elbow" />
    <child
      link="forearm" />
    <axis
      xyz="0 0 -1" />
    <dynamics
      damping="60.0"
      friction="4.0" />
  </joint>
  <link
    name="wrist">
    <inertial>
      <origin
        xyz="-0.043952 -0.063003 -0.0020958"
        rpy="0 0 0" />
      <mass
        value="2.4599" />
      <inertia
        ixx="0.0011935"
        ixy="-4.0524E-07"
        ixz="-2.2366E-06"
        iyy="0.0018813"
        iyz="-1.0459E-06"
        izz="0.0019208" />
    </inertial>
    <visual>
      <origin
        xyz="0 0 0"
        rpy="0 0 0" />
      <geometry>
        <mesh
          filename="package://urc_gazebo/urdf/meshes/wrist.STL" />
      </geometry>
      <material
        name="">
        <color
          rgba="0.75294 0.75294 0.75294 1" />
      </material>
    </visual>
    <collision>
      <origin
        xyz="0 0 0"
        rpy="0 0 0" />
      <geometry>
        <mesh
          filename="package://urc_gazebo/urdf/meshes/wrist_collision.STL" />
      </geometry>
    </collision>
  </link>
  <joint
    name="wristjoint"
    type="revolute">
    <origin
      xyz="0 0.11071 -0.63096"
      rpy="0 0 0" />
    <parent
      link="forearm" />
    <child
      link="wrist" />
    <axis
      xyz="0 -1 0" />
    <limit
      lower="-1.57"
      upper="1.57"
      effort="0"
      velocity="0" />
    <dynamics
      damping="60.0"
      friction="4.0" />
  </joint>
  <link
    name="claw">
    <inertial>
      <origin
        xyz="0.42253 3.8235E-07 6.7396E-05"
        rpy="0 0 0" />
      <mass
        value="1.4352" />
      <inertia
        ixx="0.0010292"
        ixy="1.5887E-07"
        ixz="1.398E-07"
        iyy="0.0012655"
        iyz="1.8778E-08"
        izz="0.0020608" />
    </inertial>
    <visual>
      <origin
        xyz="0 0 0"
        rpy="0 0 0" />
      <geometry>
        <mesh
          filename="package://urc_gazebo/urdf/meshes/claw.STL" />
      </geometry>
      <material
        name="">
        <color
          rgba="0.75294 0.75294 0.75294 1" />
      </material>
    </visual>
    <collision>
      <origin
        xyz="0 0 0"
        rpy="0 0 0" />
      <geometry>
        <mesh
          filename="package://urc_gazebo/urdf/meshes/claw_collision.STL" />
      </geometry>
    </collision>
  </link>
  <joint
    name="clawjoint"
    type="continuous">
    <origin
      xyz="-0.23582 -0.11071 -0.034131"
      rpy="0 0 0" />
    <parent
      link="wrist" />
    <child
      link="claw" />
    <axis
      xyz="1 0 0" />
    <dynamics
      damping="60.0"
      friction="4.0" />
  </joint>
  <link
    name="leftgripper">
    <inertial>
      <origin
        xyz="0.11047 -0.031729 -0.011112"
        rpy="0 0 0" />
      <mass
        value="0.3358" />
      <inertia
        ixx="0.00013218"
        ixy="7.9073E-05"
        ixz="2.0634E-18"
        iyy="0.00064815"
        iyz="-5.0458E-19"
        izz="0.00066862" />
    </inertial>
    <visual>
      <origin
        xyz="0 0 0"
        rpy="0 0 0" />
      <geometry>
        <mesh
          filename="package://urc_gazebo/urdf/meshes/leftgripper.STL" />
      </geometry>
      <material
        name="">
        <color
          rgba="0.89804 0.91765 0.92941 1" />
      </material>
    </visual>
    <collision>
      <origin
        xyz="0 0 0"
        rpy="0 0 0" />
      <geometry>
        <mesh
          filename="package://urc_gazebo/urdf/meshes/leftgripper_collision.STL" />
      </geometry>
    </collision>
  </link>
  <joint
    name="leftgripperjoint"
    type="revolute">
    <origin
      xyz="0.55008 0.080202 0.011112"
      rpy="0 0 0" />
    <parent
      link="claw" />
    <child
      link="leftgripper" />
    <axis
      xyz="0 0 1" />
    <limit
      lower="-0.6"
      upper="1.57"
      effort="0"
      velocity="0" />
    <dynamics
      damping="60.0"
      friction="4.0" />
  </joint>
  <link
    name="rightgripper">
    <inertial>
      <origin
        xyz="0.11047 0.031729 -0.0127"
        rpy="0 0 0" />
      <mass
        value="0.3358" />
      <inertia
        ixx="0.00013218"
        ixy="-7.9073E-05"
        ixz="-1.0118E-18"
        iyy="0.00064815"
        iyz="-3.1698E-19"
        izz="0.00066862" />
    </inertial>
    <visual>
      <origin
        xyz="0 0 0"
        rpy="0 0 0" />
      <geometry>
        <mesh
          filename="package://urc_gazebo/urdf/meshes/rightgripper.STL" />
      </geometry>
      <material
        name="">
        <color
          rgba="0.50196 0.50196 0.50196 1" />
      </material>
    </visual>
    <collision>
      <origin
        xyz="0 0 0"
        rpy="0 0 0" />
      <geometry>
        <mesh
          filename="package://urc_gazebo/urdf/meshes/rightgripper_collision.STL" />
      </geometry>
    </collision>
  </link>
  <joint
    name="rightgripperjoint"
    type="revolute">
    <origin
      xyz="0.55008 -0.080283 0.0127"
      rpy="0 0 0" />
    <parent
      link="claw" />
    <child
      link="rightgripper" />
    <axis
      xyz="0 0 -1" />
    <limit
      lower="-1.57"
      upper="0.6"
      effort="0"
      velocity="0" />
    <dynamics
      damping="60.0"
      friction="4.0" />
    <mimic
      joint="leftgripperjoint"
      multiplier="1"
      offset="0" />
  </joint>
  
  <gazebo reference="shoulderjoint">
    <implicitSpringDamper>true</implicitSpringDamper>
  </gazebo>

  <gazebo reference="bicepjoint">
    <implicitSpringDamper>true</implicitSpringDamper>
  </gazebo>

  <gazebo reference="elbowjoint">
    <implicitSpringDamper>true</implicitSpringDamper>
  </gazebo>

  <gazebo reference="forearmjoint">
    <implicitSpringDamper>true</implicitSpringDamper>
  </gazebo>

  <gazebo reference="wristjoint">
    <implicitSpringDamper>true</implicitSpringDamper>
  </gazebo>

  <gazebo reference="clawjoint">
    <implicitSpringDamper>true</implicitSpringDamper>
  </gazebo>

  <gazebo reference="leftgripperjoint">
    <implicitSpringDamper>true</implicitSpringDamper>
  </gazebo>

  <gazebo reference="rightgripperjoint">
    <implicitSpringDamper>true</implicitSpringDamper>
  </gazebo>
  
  <ros2_control name="arm_control" type="system">
    <hardware>
      <!-- TODO make a launch param to switch between real/fake hardware. You can only use ONE. -->
      <!--Use for functionality in Gazebo-->
      <plugin>gazebo_ros2_control/GazeboSystem</plugin>
      <!--Use for functionality in RViz-->
      <!-- <plugin>mock_components/GenericSystem</plugin> -->
      <plugin>ros2_control_demo_hardware/VelocityActuatorHardware</plugin>
    </hardware>

      <joint name ="shoulderjoint">
        <command_interface name="position" />
        <state_interface name="position">
          <param name="initial_value">0.0</param>
        </state_interface>
        <state_interface name="velocity"/>
        <state_interface name="effort"/>
      </joint>
      
      <joint name ="bicepjoint">
        <command_interface name="position" />
        <state_interface name="position">
          <param name="initial_value">0.0</param>
        </state_interface>
        <state_interface name="velocity"/>
        <state_interface name="effort"/>
      </joint>

      <joint name ="elbowjoint">
        <command_interface name="position" />
        <state_interface name="position">
          <param name="initial_value">0.0</param>
        </state_interface>
        <state_interface name="velocity"/>
        <state_interface name="effort"/>
      </joint>
	<joint name ="forearmjoint">
        <command_interface name="position" />
        <state_interface name="position">
          <param name="initial_value">0.0</param>
        </state_interface>
        <state_interface name="velocity"/>
        <state_interface name="effort"/>
      </joint>
	<joint name ="wristjoint">
        <command_interface name="position" />
        <state_interface name="position">
          <param name="initial_value">0.0</param>
        </state_interface>
        <state_interface name="velocity"/>
        <state_interface name="effort"/>
      </joint>
      
      <joint name ="clawjoint">
        <command_interface name="position" />
        <state_interface name="position">
          <param name="initial_value">0.0</param>
        </state_interface>
        <state_interface name="velocity"/>
        <state_interface name="effort"/>
      </joint>
      
      <joint name ="leftgripperjoint">
        <command_interface name="position" />
        <state_interface name="position">
          <param name="initial_value">0.0</param>
        </state_interface>
        <state_interface name="velocity"/>
        <state_interface name="effort"/>
      </joint>
      
      <joint name ="rightgripperjoint">
        <command_interface name="position" />
        <state_interface name="position">
          <param name="initial_value">0.0</param>
        </state_interface>
        <state_interface name="velocity"/>
        <state_interface name="effort"/>
      </joint>
    </ros2_control>
    
    <gazebo>
    <plugin name ="gazebo_ros2_control" filename="libgazebo_ros2_control.so">
      <parameters>package://urc_gazebo/urdf/config/RoboticArm_params.yaml</parameters>
    </plugin>
    </gazebo>

</robot>
