<?xml version="1.0" encoding="utf-8" ?>
<!-- This URDF was automatically created by SolidWorks to URDF Exporter! Originally created by Stephen Brawner (brawner@gmail.com) 
     Commit Version: 1.6.0-4-g7f85cfe  Build Version: 1.6.7995.38578
     For more information, please see http://wiki.ros.org/sw_urdf_exporter -->
<robot name="RoboticArm">
    <link name="world"/>
    <link name="base_link">
      <visual>
        <geometry>
          <box size="0.05 0.05 0.01"/>
        </geometry>
        <material name="body_mat"/>
      </visual>
    </link>
    <gazebo reference="base_link">
      <material>Gazebo/Green</material>
  </gazebo>
  <joint name="world_to_base" type="fixed">
    <origin rpy="0 0 0" xyz="0 0 1"/>
    <parent link="world"/>
    <child link="base_link"/>
  </joint>
    <link name="arm_base_link">
        <inertial>
            <origin xyz="0 0 -0.2" rpy="0 0 0" />
            <mass value="0.523" />
            <inertia ixx="0.010808" ixy="-4.4773E-13" ixz="-1.3408E-13" iyy="0.010807" iyz="-4.0161E-12" izz="0.00038179" />
        </inertial>
        <visual>
            <origin xyz="0 0 0" rpy="0 0 0" />
            <geometry>
                <mesh filename="$(find urc_gazebo)/urdf/meshes/base_link.STL" />
            </geometry>
            <material name="">
                <color rgba="0.89804 0.91765 0.92941 1" />
            </material>
        </visual>
        <collision>
            <origin xyz="0 0 0" rpy="0 0 0" />
            <geometry>
                <mesh filename="$(find urc_gazebo)/urdf/meshes/base_link.STL" />
            </geometry>
        </collision>
    </link>
    <joint name="arm_joint" type="fixed">
      <origin xyz="0 0 0.6"/>
      <parent link="base_link"/>
      <child link="arm_base_link"/>
      <limit effort="100" velocity="5.0"/>
    </joint>
    <link name="shoulder">
        <inertial>
            <origin xyz="-0.057629 -0.030685 0.04737" rpy="0 0 0" />
            <mass value="2.4696" />
            <inertia ixx="0.0042918" ixy="-0.00022593" ixz="-1.5804E-06" iyy="0.0032615" iyz="-7.8719E-06" izz="0.0024937" />
        </inertial>
        <visual>
            <origin xyz="0 0 0" rpy="0 0 0" />
            <geometry>
                <mesh filename="$(find urc_gazebo)/urdf/meshes/shoulder.STL" />
            </geometry>
            <material name="">
                <color rgba="0.52941 0.54902 0.54902 1" />
            </material>
        </visual>
        <collision>
            <origin xyz="0 0 0" rpy="0 0 0" />
            <geometry>
                <mesh filename="$(find urc_gazebo)/urdf/meshes/shoulder.STL" />
            </geometry>
        </collision>
    </link>
    <joint name="shoulderjoint" type="continuous">
        <origin xyz="0 0 0" rpy="0 0 0" />
        <parent link="arm_base_link" />
        <child link="shoulder" />
        <axis xyz="0 0 -1" />
        <limit effort="100" velocity="5.0"/>
    </joint>
    <link name="bicep">
        <inertial>
            <origin xyz="0.088588 -0.029308 0.077346" rpy="0 0 0" />
            <mass value="1.1771" />
            <inertia ixx="0.0063326" ixy="9.2675E-08" ixz="-3.6969E-07" iyy="0.0056923" iyz="0.0020171" izz="0.001137" />
        </inertial>
        <visual>
            <origin xyz="0 0 0" rpy="0 0 0" />
            <geometry>
                <mesh filename="$(find urc_gazebo)/urdf/meshes/bicep.STL" />
            </geometry>
            <material name="">
                <color rgba="0.89804 0.91765 0.92941 1" />
            </material>
        </visual>
        <collision>
            <origin xyz="0 0 0" rpy="0 0 0" />
            <geometry>
                <mesh filename="$(find urc_gazebo)/urdf/meshes/bicep.STL" />
            </geometry>
        </collision>
    </link>
    <joint name="bicepjoint" type="continuous">
        <origin xyz="0.06843 0.032977 0.041262" rpy="1.5708 0 2.9348" />
        <parent link="shoulder" />
        <child link="bicep" />
        <axis xyz="-1 0 0" />
        <limit effort="100" velocity="5.0"/>
    </joint>
    <link name="elbow">
        <inertial>
            <origin xyz="-0.12752 -0.060357 -0.047394" rpy="0 0 0" />
            <mass value="2.3313" />
            <inertia ixx="0.0027669" ixy="-3.2722E-07" ixz="6.4659E-07" iyy="0.0017335" iyz="-0.00041577" izz="0.0024931" />
        </inertial>
        <visual>
            <origin xyz="0 0 0" rpy="0 0 0" />
            <geometry>
                <mesh filename="$(find urc_gazebo)/urdf/meshes/elbow.STL" />
            </geometry>
            <material name="">
                <color rgba="0.65098 0.61961 0.58824 1" />
            </material>
        </visual>
        <collision>
            <origin xyz="0 0 0" rpy="0 0 0" />
            <geometry>
                <mesh filename="$(find urc_gazebo)/urdf/meshes/elbow.STL" />
            </geometry>
        </collision>
    </link>
    <joint name="elbowjoint" type="continuous">
        <origin xyz="0.1204 -0.12377 0.32658" rpy="0 0 0" />
        <parent link="bicep" />
        <child link="elbow" />
        <axis xyz="1 0 0" />
        <limit effort="100" velocity="5.0"/>
    </joint>
    <link name="forearm">
        <inertial>
            <origin xyz="-0.31229 -9.7716E-06 -5.9818E-05" rpy="0 0 0" />
            <mass value="1.1353" />
            <inertia ixx="0.00033576" ixy="2.1424E-06" ixz="-2.1741E-06" iyy="0.0036528" iyz="1.5007E-05" izz="0.0036552" />
        </inertial>
        <visual>
            <origin xyz="0 0 0" rpy="0 0 0" />
            <geometry>
                <mesh filename="$(find urc_gazebo)/urdf/meshes/forearm.STL" />
            </geometry>
            <material name="">
                <color rgba="0.52941 0.54902 0.54902 1" />
            </material>
        </visual>
        <collision>
            <origin xyz="0 0 0" rpy="0 0 0" />
            <geometry>
                <mesh filename="$(find urc_gazebo)/urdf/meshes/forearm.STL" />
            </geometry>
        </collision>
    </link>
    <joint name="forearmjoint" type="continuous">
        <origin xyz="-0.060202 -0.19694 -0.1385" rpy="-1.5708 0.41929 -1.5708" />
        <parent link="elbow" />
        <child link="forearm" />
        <axis xyz="-1 0 0" />
        <limit effort="100" velocity="5.0"/>
    </joint>
    
    <!-- links and joints here -->
    
    
    <transmission name="trans_shoulderjoint">
        <type>transmission_interface/SimpleTransmission</type>
        <joint name="shoulderjoint">
            <hardwareInterface>hardware_interface/EffortJointInterface</hardwareInterface>
        </joint>
        <actuator name="shoulderjoint_motor">
            <hardwareInterface>hardware_interface/EffortJointInterface</hardwareInterface>
            <mechanicalReduction>1</mechanicalReduction>
        </actuator>
    </transmission>
    <transmission name="trans_bicepjoint">
        <type>transmission_interface/SimpleTransmission</type>
        <joint name="bicepjoint">
            <hardwareInterface>hardware_interface/EffortJointInterface</hardwareInterface>
        </joint>
        <actuator name="bicepjoint_motor">
            <hardwareInterface>hardware_interface/EffortJointInterface</hardwareInterface>
            <mechanicalReduction>1</mechanicalReduction>
        </actuator>
    </transmission>
    <transmission name="trans_elbowjoint">
        <type>transmission_interface/SimpleTransmission</type>
        <joint name="elbowjoint">
            <hardwareInterface>hardware_interface/EffortJointInterface</hardwareInterface>
        </joint>
        <actuator name="elbowjoint_motor">
            <hardwareInterface>hardware_interface/EffortJointInterface</hardwareInterface>
            <mechanicalReduction>1</mechanicalReduction>
        </actuator>
    </transmission>
    <transmission name="trans_forearmjoint">
        <type>transmission_interface/SimpleTransmission</type>
        <joint name="forearmjoint">
            <hardwareInterface>hardware_interface/EffortJointInterface</hardwareInterface>
        </joint>
        <actuator name="forearmjoint_motor">
            <hardwareInterface>hardware_interface/EffortJointInterface</hardwareInterface>
            <mechanicalReduction>1</mechanicalReduction>
        </actuator>
    </transmission>
    
    <!-- transmission stuff here -->
    
    <ros2_control name="GazeboSystem" type="system">
    <hardware>
      <plugin>gazebo_ros2_control/GazeboSystem</plugin>
    </hardware>
    <joint name ="arm_joint">
        <command_interface name="position" />
        <state_interface name="position">
          <param name="initial_value">0.0</param>
        </state_interface>
        <state_interface name="velocity"/>
      </joint>
      
      <joint name ="shoulderjoint">
        <command_interface name="position" />
        <state_interface name="position">
          <param name="initial_value">0.0</param>
        </state_interface>
        <state_interface name="velocity"/>
      </joint>
      
      <joint name ="bicepjoint">
        <command_interface name="position" />
        <state_interface name="position">
          <param name="initial_value">0.0</param>
        </state_interface>
        <state_interface name="velocity"/>
      </joint>
      
      <joint name ="elbowjoint">
        <command_interface name="position" />
        <state_interface name="position">
          <param name="initial_value">0.0</param>
        </state_interface>
        <state_interface name="velocity"/>
      </joint>
      
      <joint name ="forearmjoint">
        <command_interface name="position" />
        <state_interface name="position">
          <param name="initial_value">0.0</param>
        </state_interface>
        <state_interface name="velocity"/>
      </joint>
      
      
      <!-- joints go here -->
      
    </ros2_control>
  <gazebo>
    <plugin name ="gazebo_ros2_control" filename="libgazebo_ros2_control.so">
      <!-- problematic: yaml parse crashes simulation-->
      <parameters>$(find urc_gazebo)/urdf/config/RoboticArm_params.yaml</parameters>
    </plugin>
  </gazebo>
</robot>
