<mujoco model="walli">
  <compiler angle="radian"/>

  <asset>
    <mesh name="spine_collision" file="spine_collision.STL"/>
    <mesh name="shoulder_collision" file="shoulder_collision.STL"/>
    <mesh name="bicep_collision" file="bicep_collision.STL"/>
    <mesh name="elbow_collision" file="elbow_collision.STL"/>
    <mesh name="wrist_collision" file="wrist_collision.STL"/>
    <mesh name="claw_collision" file="claw_collision.STL"/>
    <mesh name="rightgripper_collision" file="rightgripper_collision.STL"/>
    <mesh name="leftgripper_collision" file="leftgripper_collision.STL"/>
  </asset>

  <worldbody>
    <geom pos="0 0 0.4" quat="1 0 0 0" type="mesh" mesh="spine_collision"/>
    <body name="shoulder" pos="0 0 0.4">
      <inertial pos="0.020518 0.053038 -0.052389" quat="0.707751 0.706462 3.88068e-05 0.000172548" mass="1.3264" diaginertia="0.0025022 0.0020646 0.000926586"/>
      <joint name="shoulderjoint" pos="0 0 0" axis="0 0 1" range="-3.14 3.14" damping="0.01" frictionloss="4"/>
      <geom type="mesh" mesh="shoulder_collision"/>
      <body name="bicep" pos="0.046323 -0.047405 -0.052413">
        <inertial pos="0.12731 0.047938 0.11952" quat="0 0.397204 0 0.91773" mass="0.56899" diaginertia="0.00588449 0.0058314 0.000114613"/>
        <joint name="bicepjoint" pos="0 0 0" axis="0 -1 0" range="-3.14 3.14" damping="60" frictionloss="4"/>
        <geom type="mesh" mesh="bicep_collision"/>
        <body name="elbow" pos="0.25459 8.2754e-05 0.23905">
          <inertial pos="0.057399 0.088305 0.031812" quat="0.000194825 0.706082 -0.000407168 0.70813" mass="1.7547" diaginertia="0.00623213 0.004637 0.00211636"/>
          <joint name="elbowjoint" pos="0 0 0" axis="0 -1 0" range="-3.14 3.14" damping="60" frictionloss="4"/>
          <geom type="mesh" mesh="elbow_collision"/>
          <body name="wrist" pos="0.35396 0.0035964 0.048704">
            <inertial pos="-0.015666 0.09009 0.02975" quat="0.488316 0.511378 -0.488513 0.511268" mass="1.641" diaginertia="0.0029203 0.00209296 0.00139834"/>
            <joint name="wristjoint" pos="0 0 0" axis="0 -1 0" range="-3.14 3.14" damping="0.01" frictionloss="4"/>
            <geom type="mesh" mesh="wrist_collision"/>
            <body name="claw" pos="0.34674 0.047161 0.046323">
              <inertial pos="-0.12039 -3.2707e-05 8.7622e-05" quat="0.500922 0.4991 -0.500876 0.499098" mass="0.68517" diaginertia="0.0015578 0.000858661 0.000766179"/>
              <joint name="clawjoint" pos="0 0 0" axis="1 0 0" range="-3.14 3.14" damping="0.01" frictionloss="4"/>
              <geom type="mesh" mesh="claw_collision"/>
              <body name="rightgripper" pos="-0.030801 -0.080243 0.013053">
                <inertial pos="0.10255 -0.010123 -0.013053" quat="-0.0377048 0.706101 0.0377048 0.706101" mass="0.3358" diaginertia="0.00066862 0.000604123 0.000176217"/>
                <joint name="rightgripperjoint" pos="0 0 0" axis="0 0 -1" range="-1.57 0.6" damping="0.01" frictionloss="0.01"/>
                <geom type="mesh" mesh="rightgripper_collision"/>
              </body>
              <body name="leftgripper" pos="-0.030801 0.080243 0.013053">
                <inertial pos="0.10255 0.010123 -0.013053" quat="0.0377048 0.706101 -0.0377048 0.706101" mass="0.3358" diaginertia="0.00066862 0.000604123 0.000176217"/>
                <joint name="leftgripperjoint" pos="0 0 0" axis="0 0 1" range="-0.6 1.57" damping="0.01" frictionloss="0.01"/>
                <geom type="mesh" mesh="leftgripper_collision"/>
              </body>
            </body>
          </body>
        </body>
      </body>
    </body>
  </worldbody>

  <actuator>
    <motor name="shoulder" joint="shoulderjoint" ctrlrange="-200 200"/>
    <motor name="bicep" joint="bicepjoint" ctrlrange="-200 200"/>
    <motor name="elbow" joint="elbowjoint" ctrlrange="-200 200"/>
    <motor name="wrist" joint="wristjoint" ctrlrange="-300 300"/>
    <motor name="claw" joint="clawjoint" ctrlrange="-40 40"/>
    <motor name="leftgripper" joint="leftgripperjoint" ctrlrange="-40 40"/>
  </actuator>
</mujoco>
