<?xml version="1.0"?>

<robot xmlns:xacro="http://www.ros.org/wiki/xacro">
    <xacro:macro name="drivebase" params="wheel_radius wheel_thickness mu mu2 approximate">
        <link name="base_link">
            <inertial>
                <origin xyz="-0.22771 0.0020794 0.13424" rpy="0 0 0" />
                <mass value="1.584994" />
                <inertia ixx="0.017201" ixy="-2.0986E-11" ixz="5.8899E-06" iyy="0.0028906"
                    iyz="5.0336E-07"
                    izz="0.019124" />
            </inertial>
            <visual>
                <origin xyz="0 0 0" rpy="0 0 0" />
                <geometry>
                    <mesh filename="file://$(find urc_hw_description)/urdf/meshes/visual/base_link.STL" />
                </geometry>
            </visual>
            <collision>
                <origin xyz="0 0 0" rpy="0 0 0" />
                <geometry>
                    <mesh
                        filename="file://$(find urc_hw_description)/urdf/meshes/collision/base_link_collision.STL" />
                </geometry>
            </collision>
        </link>

        <!-- ROCKERS -->
        <link name="rightrocker">
            <inertial>
                <origin xyz="0.062687 0.034616 -0.016048" rpy="0 0 0" />
                <mass value="1.387336" />
                <inertia
                    ixx="0.002956" ixy="-0.000001489324" ixz="-0.000008103407"
                    iyy="0.02924" iyz="0.00007112"
                    izz="0.02832" />
            </inertial>
            <visual>
                <origin xyz="0 0 0" rpy="0 0 0" />
                <geometry>
                    <mesh filename="file://$(find urc_hw_description)/urdf/meshes/visual/rightrocker.STL" />
                </geometry>
            </visual>
            <collision>
                <origin xyz="0 0 0" rpy="0 0 0" />
                <geometry>
                    <mesh
                        filename="file://$(find urc_hw_description)/urdf/meshes/collision/rightrocker_collision.STL" />
                </geometry>
            </collision>
        </link>
        <joint name="rightrockerjoint" type="revolute">
            <origin xyz="-0.194 -0.33715 0.080295" rpy="0 0 0" />
            <parent link="base_link" />
            <child link="rightrocker" />
            <axis xyz="0 1 0" />
            <limit effort="0.0" lower="-0.24" upper="0.24" velocity="100.0" />
            <dynamics friction="1.0" damping="0.1" />
        </joint>

        <link name="leftrocker">
            <inertial>
                <origin xyz="0.065435 -0.034981 -0.01685" rpy="0 0 0" />
                <mass value="1.387336" />
                <inertia
                    ixx="0.002956" ixy="-0.000001489324" ixz="-0.000008103407"
                    iyy="0.02924" iyz="0.00007112"
                    izz="0.02832" />
            </inertial>
            <visual>
                <origin xyz="0 0 0" rpy="0 0 0" />
                <geometry>
                    <mesh filename="file://$(find urc_hw_description)/urdf/meshes/visual/leftrocker.STL" />
                </geometry>
            </visual>
            <collision>
                <origin xyz="0 0 0" rpy="0 0 0" />
                <geometry>
                    <mesh
                        filename="file://$(find urc_hw_description)/urdf/meshes/collision/leftrocker_collision.STL" />
                </geometry>
            </collision>
        </link>
        <joint name="leftrockerjoint" type="revolute">
            <origin xyz="-0.19241 0.33715 0.080257" rpy="0 0 0" />
            <parent link="base_link" />
            <child link="leftrocker" />
            <axis xyz="0 1 0" />
            <limit effort="0.0" lower="-0.24" upper="0.24" velocity="100.0" />
            <dynamics friction="1.0" damping="0.1" />
        </joint>

        <!-- BOGIES -->

        <link name="rightbogie">
            <inertial>
                <origin xyz="-6.8787E-09 0.032385 -0.015429" rpy="0 0 0" />
                <mass value="0.66758" />
                <inertia ixx="0.0019756" ixy="-5.9804E-10" ixz="9.4624E-11" iyy="0.0044836"
                    iyz="2.6509E-13" izz="0.003846" />
            </inertial>
            <visual>
                <origin xyz="0 0 0" rpy="0 0 0" />
                <geometry>
                    <mesh filename="file://$(find urc_hw_description)/urdf/meshes/visual/rightbogie.STL" />
                </geometry>
            </visual>
            <collision>
                <origin xyz="0 0 0" rpy="0 0 0" />
                <geometry>
                    <mesh
                        filename="file://$(find urc_hw_description)/urdf/meshes/collision/rightbogie_collision.STL" />
                </geometry>
            </collision>
        </link>
        <joint name="rightbogiejoint" type="revolute">
            <origin xyz="0.24177 -0.00254 -0.074203" rpy="0 0 0" />
            <parent link="rightrocker" />
            <child link="rightbogie" />
            <axis xyz="0 1 0" />
            <limit effort="0.0" lower="-0.24" upper="0.24" velocity="100.0" />
            <dynamics friction="1.0" damping="0.1" />
        </joint>

        <link name="leftbogie">
            <inertial>
                <origin xyz="-6.8787E-09 -0.032385 -0.015429" rpy="0 0 0" />
                <mass value="0.66758" />
                <inertia ixx="0.0019756" ixy="-5.9804E-10" ixz="9.4624E-11" iyy="0.0044836"
                    iyz="2.6509E-13" izz="0.003846" />
            </inertial>
            <visual>
                <origin xyz="0 0 0" rpy="0 0 0" />
                <geometry>
                    <mesh filename="file://$(find urc_hw_description)/urdf/meshes/visual/leftbogie.STL" />
                </geometry>
            </visual>
            <collision>
                <origin xyz="0 0 0" rpy="0 0 0" />
                <geometry>
                    <mesh
                        filename="file://$(find urc_hw_description)/urdf/meshes/collision/leftbogie_collision.STL" />
                </geometry>
            </collision>
        </link>
        <joint name="leftbogiejoint" type="revolute">
            <origin xyz="0.24182 0.00254 -0.073984" rpy="0 0 0" />
            <parent link="leftrocker" />
            <child link="leftbogie" />
            <axis xyz="0 1 0" />
            <limit effort="0.0" lower="-0.24" upper="0.24" velocity="100.0" />
            <dynamics friction="1.0" damping="0.1" />
        </joint>

        <!-- WHEELS -->

        <link name="right_rear_wheel">
            <inertial>
                <origin xyz="0 0 0" rpy="0 0 0" />
                <mass value="0.283642" />
                <inertia ixx="0.000391" ixy="0.00000123962" ixz="5.52582e-7" iyy="0.0004716"
                    iyz="-0.000002082042" izz="0.000391" />
            </inertial>
            <visual>
                <origin xyz="0 0 0" rpy="${pi/2} 0 0" />
                <geometry>
                    <cylinder radius="${wheel_radius}" length="${wheel_thickness}" />
                </geometry>
            </visual>
            <collision>
                <origin xyz="0 0 0" rpy="${pi/2} 0 0" />
                <geometry>
                    <cylinder radius="${wheel_radius}" length="${wheel_thickness}" />
                </geometry>
            </collision>
        </link>
        <joint name="right_rear_wheel_joint" type="continuous">
            <origin xyz="-0.36316 -0.04 -0.19158" rpy="0 0 0" />
            <parent link="rightrocker" />
            <child link="right_rear_wheel" />
            <axis xyz="0 1 0" />
            <dynamics friction="0.3125" damping="0.1" />
        </joint>

        <link name="right_front_wheel">
            <inertial>
                <origin xyz="0 0 0" rpy="0 0 0" />
                <mass value="0.283642" />
                <inertia ixx="0.000391" ixy="0.00000123962" ixz="5.52582e-7" iyy="0.0004716"
                    iyz="-0.000002082042" izz="0.000391" />
            </inertial>
            <visual>
                <origin xyz="0 0 0" rpy="${pi/2} 0 0" />
                <geometry>
                    <cylinder radius="${wheel_radius}" length="${wheel_thickness}" />
                </geometry>
            </visual>
            <collision>
                <origin xyz="0 0 0" rpy="${pi/2} 0 0" />
                <geometry>
                    <cylinder radius="${wheel_radius}" length="${wheel_thickness}" />
                </geometry>
            </collision>
        </link>
        <joint name="right_front_wheel_joint" type="continuous">
            <origin xyz="0.20139 -0.04 -0.11671" rpy="0 0 0" />
            <parent link="rightbogie" />
            <child link="right_front_wheel" />
            <axis xyz="0 1 0" />
            <dynamics friction="0.3125" damping="0.1" />
        </joint>

        <link name="right_center_wheel">
            <inertial>
                <origin xyz="0 0 0" rpy="0 0 0" />
                <mass value="0.283642" />
                <inertia ixx="0.000391" ixy="0.00000123962" ixz="5.52582e-7" iyy="0.0004716"
                    iyz="-0.000002082042" izz="0.000391" />
            </inertial>
            <visual>
                <origin xyz="0 0 0" rpy="${pi/2} 0 0" />
                <geometry>
                    <cylinder radius="${wheel_radius}" length="${wheel_thickness}" />
                </geometry>
            </visual>
            <collision>
                <origin xyz="0 0 0" rpy="${pi/2} 0 0" />
                <geometry>
                    <cylinder radius="${wheel_radius}" length="${wheel_thickness}" />
                </geometry>
            </collision>
        </link>
        <joint name="right_center_wheel_joint" type="continuous">
            <origin xyz="-0.20177 -0.04 -0.11606" rpy="0 0 0" />
            <parent link="rightbogie" />
            <child link="right_center_wheel" />
            <axis xyz="0 1 0" />
            <dynamics friction="0.3125" damping="0.1" />
        </joint>


        <link name="left_rear_wheel">
            <inertial>
                <origin xyz="0 0 0" rpy="0 0 0" />
                <mass value="0.283642" />
                <inertia ixx="0.000391" ixy="0.00000123962" ixz="5.52582e-7" iyy="0.0004716"
                    iyz="-0.000002082042" izz="0.000391" />
            </inertial>
            <visual>
                <origin xyz="0 0 0" rpy="${pi/2} 0 0" />
                <geometry>
                    <cylinder radius="${wheel_radius}" length="${wheel_thickness}" />
                </geometry>
            </visual>
            <collision>
                <origin xyz="0 0 0" rpy="${pi/2} 0 0" />
                <geometry>
                    <cylinder radius="${wheel_radius}" length="${wheel_thickness}" />
                </geometry>
            </collision>
        </link>
        <joint name="left_rear_wheel_joint" type="continuous">
            <origin xyz="-0.36266 0.04 -0.19248" rpy="0 0 0" />
            <parent link="leftrocker" />
            <child link="left_rear_wheel" />
            <axis xyz="0 1 0" />
            <dynamics friction="0.3125" damping="0.1" />
        </joint>

        <link name="left_front_wheel">
            <inertial>
                <origin xyz="0 0 0" rpy="0 0 0" />
                <mass value="0.283642" />
                <inertia ixx="0.000391" ixy="0.00000123962" ixz="5.52582e-7" iyy="0.0004716"
                    iyz="-0.000002082042" izz="0.000391" />
            </inertial>
            <visual>
                <origin xyz="0 0 0" rpy="${pi/2} 0 0" />
                <geometry>
                    <cylinder radius="${wheel_radius}" length="${wheel_thickness}" />
                </geometry>
            </visual>
            <collision>
                <origin xyz="0 0 0" rpy="${pi/2} 0 0" />
                <geometry>
                    <cylinder radius="${wheel_radius}" length="${wheel_thickness}" />
                </geometry>
            </collision>
        </link>
        <joint name="left_front_wheel_joint" type="continuous">
            <origin xyz="0.20177 0.04 -0.11606" rpy="0 0 0" />
            <parent link="leftbogie" />
            <child link="left_front_wheel" />
            <axis xyz="0 1 0" />
            <dynamics friction="0.3125" damping="0.1" />
        </joint>

        <link name="left_center_wheel">
            <inertial>
                <origin xyz="0 0 0" rpy="0 0 0" />
                <mass value="0.283642" />
                <inertia ixx="0.000391" ixy="0.00000123962" ixz="5.52582e-7" iyy="0.0004716"
                    iyz="-0.000002082042" izz="0.000391" />
            </inertial>
            <visual>
                <origin xyz="0 0 0" rpy="${pi/2} 0 0" />
                <geometry>
                    <cylinder radius="${wheel_radius}" length="${wheel_thickness}" />
                </geometry>
            </visual>
            <collision>
                <origin xyz="0 0 0" rpy="${pi/2} 0 0" />
                <geometry>
                    <cylinder radius="${wheel_radius}" length="${wheel_thickness}" />
                </geometry>
            </collision>
        </link>
        <joint name="left_center_wheel_joint" type="continuous">
            <origin xyz="-0.20139 0.04 -0.11671" rpy="0 0 0" />
            <parent link="leftbogie" />
            <child link="left_center_wheel" />
            <axis xyz="0 1 0" />
            <dynamics friction="0.3125" damping="0.1" />
        </joint>

        <gazebo reference="base_link">
            <material>Gazebo/Grey</material>
        </gazebo>
        <gazebo reference="rightrocker">
            <material>Gazebo/Grey</material>
        </gazebo>
        <gazebo reference="rightbogie">
            <material>Gazebo/Grey</material>
        </gazebo>
        <gazebo reference="leftrocker">
            <material>Gazebo/Grey</material>
        </gazebo>
        <gazebo reference="leftbogie">
            <material>Gazebo/Grey</material>
        </gazebo>

        <gazebo reference="right_rear_wheel">
            <material>Gazebo/Black</material>
            <kp>1e6</kp>
            <kd>100.0</kd>
            <mu1>${mu}</mu1>
            <mu2>${mu2}</mu2>
            <fdir1>1 0 0</fdir1>
            <minDepth>0.003</minDepth>
        </gazebo>
        <gazebo reference="right_front_wheel">
            <material>Gazebo/Black</material>
            <kp>1e6</kp>
            <kd>100.0</kd>
            <mu1>${mu}</mu1>
            <mu2>${mu2}</mu2>
            <fdir1>1 0 0</fdir1>
            <minDepth>0.003</minDepth>
        </gazebo>
        <gazebo reference="right_center_wheel">
            <material>Gazebo/Black</material>
            <kp>1e6</kp>
            <kd>100.0</kd>
            <mu1>${mu}</mu1>
            <mu2>${mu2}</mu2>
            <fdir1>1 0 0</fdir1>
            <minDepth>0.003</minDepth>
        </gazebo>
        <gazebo reference="left_rear_wheel">
            <material>Gazebo/Black</material>
            <kp>1e6</kp>
            <kd>100.0</kd>
            <mu1>${mu}</mu1>
            <mu2>${mu2}</mu2>
            <fdir1>1 0 0</fdir1>
            <minDepth>0.003</minDepth>
        </gazebo>
        <gazebo reference="left_front_wheel">
            <material>Gazebo/Black</material>
            <kp>1e6</kp>
            <kd>100.0</kd>
            <mu1>${mu}</mu1>
            <mu2>${mu2}</mu2>
            <fdir1>1 0 0</fdir1>
            <minDepth>0.003</minDepth>
        </gazebo>
        <gazebo reference="left_center_wheel">
            <material>Gazebo/Black</material>
            <kp>1e6</kp>
            <kd>100.0</kd>
            <mu1>${mu}</mu1>
            <mu2>${mu2}</mu2>
            <fdir1>1 0 0</fdir1>
            <minDepth>0.003</minDepth>
        </gazebo>
    </xacro:macro>
</robot>