<?xml version="1.0"?>

<robot xmlns:xacro="http://www.ros.org/wiki/xacro" name="robot_name">
    <xacro:macro name="arm">
        <link name="spine">
            <inertial>
                <origin xyz="-4.2872E-05 -0.00027225 -0.21303" rpy="0 0 0" />
                <mass value="0.9682" />
                <inertia ixx="0.01233" ixy="-4.9034E-07" ixz="-3.3052E-10" iyy="0.012329"
                    iyz="-6.338E-06"
                    izz="0.00039532" />
            </inertial>
            <visual>
                <origin xyz="0 0 0" rpy="0 0 0" />
                <geometry>
                    <mesh filename="file://$(find urc_gazebo)/urdf/meshes/visual/spine.STL" />
                </geometry>
            </visual>
            <collision>
                <origin xyz="0 0 0" rpy="0 0 0" />
                <geometry>
                    <mesh
                        filename="file://$(find urc_gazebo)/urdf/meshes/collision/spine_collision.STL" />
                </geometry>
            </collision>
        </link>
        <joint name="spinejoint" type="fixed">
            <origin xyz="0.000513666061109697 0.00028388502121135 0.630050810000002" rpy="0 0 0" />
            <parent link="base_link" />
            <child link="spine" />
            <axis xyz="0 0 0" />
        </joint>
        <link name="shoulder">
            <inertial>
                <origin xyz="0.020518 0.053038 -0.052389" rpy="0 0 0" />
                <mass value="1.3264" />
                <inertia ixx="0.0025022" ixy="4.7083E-07" ixz="8.2027E-08" iyy="0.00092659"
                    iyz="2.0751E-06" izz="0.0020646" />
            </inertial>
            <visual>
                <origin xyz="0 0 0" rpy="0 0 0" />
                <geometry>
                    <mesh filename="file://$(find urc_gazebo)/urdf/meshes/visual/shoulder.STL" />
                </geometry>
            </visual>
            <collision>
                <origin xyz="0 0 0" rpy="0 0 0" />
                <geometry>
                    <mesh
                        filename="file://$(find urc_gazebo)/urdf/meshes/collision/shoulder_collision.STL" />
                </geometry>
            </collision>
        </link>
        <joint name="shoulderjoint" type="revolute">
            <origin xyz="0 0 0" rpy="0 0 0" />
            <parent link="spine" />
            <child link="shoulder" />
            <axis xyz="0 0 1" />
            <limit lower="-3.14" upper="3.14" effort="0" velocity="0" />
            <dynamics damping="0.01" friction="4" />
        </joint>
        <link name="bicep">
            <inertial>
                <origin xyz="0.12731 0.047938 0.11952" rpy="0 0 0" />
                <mass value="0.56899" />
                <inertia ixx="0.0028177" ixy="-3.8181E-18" ixz="-0.0028792" iyy="0.0058314"
                    iyz="-3.5192E-18" izz="0.0031814" />
            </inertial>
            <visual>
                <origin xyz="0 0 0" rpy="0 0 0" />
                <geometry>
                    <mesh filename="file://$(find urc_gazebo)/urdf/meshes/visual/bicep.STL" />
                </geometry>
            </visual>
            <collision>
                <origin xyz="0 0 0" rpy="0 0 0" />
                <geometry>
                    <mesh
                        filename="file://$(find urc_gazebo)/urdf/meshes/collision/bicep_collision.STL" />
                </geometry>
            </collision>
        </link>
        <joint name="bicepjoint" type="revolute">
            <origin xyz="0.046323 -0.047405 -0.052413" rpy="0 0 0" />
            <parent link="shoulder" />
            <child link="bicep" />
            <axis xyz="0 -1 0" />
            <limit lower="-3.14" upper="3.14" effort="0" velocity="0" />
            <dynamics damping="60" friction="4" />
        </joint>
        <link name="elbow">
            <inertial>
                <origin xyz="0.057399 0.088305 0.031812" rpy="0 0 0" />
                <mass value="1.7547" />
                <inertia ixx="0.0021164" ixy="2.1484E-06" ixz="-1.1917E-05" iyy="0.004637"
                    iyz="-4.7083E-07" izz="0.0062321" />
            </inertial>
            <visual>
                <origin xyz="0 0 0" rpy="0 0 0" />
                <geometry>
                    <mesh filename="file://$(find urc_gazebo)/urdf/meshes/visual/elbow.STL" />
                </geometry>
            </visual>
            <collision>
                <origin xyz="0 0 0" rpy="0 0 0" />
                <geometry>
                    <mesh
                        filename="file://$(find urc_gazebo)/urdf/meshes/collision/elbow_collision.STL" />
                </geometry>
            </collision>
        </link>
        <joint name="elbowjoint" type="revolute">
            <origin xyz="0.25459 8.2754E-05 0.23905" rpy="0 0 0" />
            <parent link="bicep" />
            <child link="elbow" />
            <axis xyz="0 -1 0" />
            <limit lower="-3.14" upper="3.14" effort="0" velocity="0" />
            <dynamics damping="60" friction="4" />
        </joint>
        <link name="wrist">
            <inertial>
                <origin xyz="-0.015666 0.09009 0.02975" rpy="0 0 0" />
                <mass value="1.641" />
                <inertia ixx="0.0020915" ixy="3.1784E-05" ixz="-5.5989E-08" iyy="0.0013998"
                    iyz="-4.6737E-07" izz="0.0029203" />
            </inertial>
            <visual>
                <origin xyz="0 0 0" rpy="0 0 0" />
                <geometry>
                    <mesh filename="file://$(find urc_gazebo)/urdf/meshes/visual/wrist.STL" />
                </geometry>
            </visual>
            <collision>
                <origin xyz="0 0 0" rpy="0 0 0" />
                <geometry>
                    <mesh
                        filename="file://$(find urc_gazebo)/urdf/meshes/collision/wrist_collision.STL" />
                </geometry>
            </collision>
        </link>
        <joint name="wristjoint" type="revolute">
            <origin xyz="0.35396 0.0035964 0.048704" rpy="0 0 0" />
            <parent link="elbow" />
            <child link="wrist" />
            <axis xyz="0 -1 0" />
            <limit lower="-3.14" upper="3.14" effort="0" velocity="0" />
            <dynamics damping="0.01" friction="4" />
        </joint>
        <link name="claw">
            <inertial>
                <origin xyz="-0.12039 -3.2707E-05 8.7622E-05" rpy="0 0 0" />
                <mass value="0.68517" />
                <inertia ixx="0.00085866" ixy="-3.3295E-07" ixz="3.4281E-08" iyy="0.00076618"
                    iyz="3.4515E-08" izz="0.0015578" />
            </inertial>
            <visual>
                <origin xyz="0 0 0" rpy="0 0 0" />
                <geometry>
                    <mesh filename="file://$(find urc_gazebo)/urdf/meshes/visual/claw.STL" />
                </geometry>
            </visual>
            <collision>
                <origin xyz="0 0 0" rpy="0 0 0" />
                <geometry>
                    <mesh
                        filename="file://$(find urc_gazebo)/urdf/meshes/collision/claw_collision.STL" />
                </geometry>
            </collision>
        </link>
        <joint name="clawjoint" type="revolute">
            <origin xyz="0.34674 0.047161 0.046323" rpy="0 0 0" />
            <parent link="wrist" />
            <child link="claw" />
            <axis xyz="1 0 0" />
            <limit lower="-3.14" upper="3.14" effort="0" velocity="0" />
            <dynamics damping="0.01" friction="4" />
        </joint>
        <link name="rightgripper">
            <inertial>
                <origin xyz="0.10255 -0.010123 -0.013053" rpy="0 0 0" />
                <mass value="0.3358" />
                <inertia ixx="0.00018107" ixy="-4.531E-05" ixz="-1.2298E-19" iyy="0.00059927"
                    iyz="7.8324E-19" izz="0.00066862" />
            </inertial>
            <visual>
                <origin xyz="0 0 0" rpy="0 0 0" />
                <geometry>
                    <mesh filename="file://$(find urc_gazebo)/urdf/meshes/visual/rightgripper.STL" />
                </geometry>
            </visual>
            <collision>
                <origin xyz="0 0 0" rpy="0 0 0" />
                <geometry>
                    <mesh
                        filename="file://$(find urc_gazebo)/urdf/meshes/collision/rightgripper_collision.STL" />
                </geometry>
            </collision>
        </link>
        <joint name="rightgripperjoint" type="revolute">
            <origin xyz="-0.030801 -0.080243 0.013053" rpy="0 0 0" />
            <parent link="claw" />
            <child link="rightgripper" />
            <axis xyz="0 0 -1" />
            <limit lower="-1.57" upper="0.6" effort="0" velocity="0" />
            <dynamics damping="0.01" friction="0.01" />
        </joint>
        <link name="leftgripper">
            <inertial>
                <origin xyz="0.10255 0.010123 -0.013053" rpy="0 0 0" />
                <mass value="0.3358" />
                <inertia ixx="0.00018107" ixy="4.531E-05" ixz="3.3128E-18" iyy="0.00059927"
                    iyz="5.2882E-19" izz="0.00066862" />
            </inertial>
            <visual>
                <origin xyz="0 0 0" rpy="0 0 0" />
                <geometry>
                    <mesh filename="file://$(find urc_gazebo)/urdf/meshes/visual/leftgripper.STL" />
                </geometry>
            </visual>
            <collision>
                <origin xyz="0 0 0" rpy="0 0 0" />
                <geometry>
                    <mesh
                        filename="file://$(find urc_gazebo)/urdf/meshes/collision/leftgripper_collision.STL" />
                </geometry>
            </collision>
        </link>
        <joint name="leftgripperjoint" type="revolute">
            <origin xyz="-0.030801 0.080243 0.013053" rpy="0 0 0" />
            <parent link="claw" />
            <child link="leftgripper" />
            <axis xyz="0 0 1" />
            <limit lower="-0.6" upper="1.57" effort="0" velocity="0" />
            <dynamics damping="0.01" friction="0.01" />
            <mimic joint="rightgripperjoint" multiplier="1" offset="0" />
        </joint>

        <gazebo reference="spine">
            <material>Gazebo/Grey</material>
        </gazebo>
        <gazebo reference="shoulder">
            <material>Gazebo/Grey</material>
        </gazebo>
        <gazebo reference="bicep">
            <material>Gazebo/Grey</material>
        </gazebo>
        <gazebo reference="elbow">
            <material>Gazebo/Grey</material>
        </gazebo>
        <gazebo reference="wrist">
            <material>Gazebo/Grey</material>
        </gazebo>
        <gazebo reference="claw">
            <material>Gazebo/Grey</material>
        </gazebo>
        <gazebo reference="rightgripper">
            <material>Gazebo/Grey</material>
        </gazebo>
        <gazebo reference="leftgripper">
            <material>Gazebo/Grey</material>
        </gazebo>
        <gazebo reference="shoulderjoint">
            <implicitSpringDamper>true</implicitSpringDamper>
        </gazebo>
        <gazebo reference="bicepjoint">
            <implicitSpringDamper>true</implicitSpringDamper>
        </gazebo>
        <gazebo reference="elbowjoint">
            <implicitSpringDamper>true</implicitSpringDamper>
        </gazebo>
        <gazebo reference="wristjoint">
            <implicitSpringDamper>true</implicitSpringDamper>
        </gazebo>
        <gazebo reference="clawjoint">
            <implicitSpringDamper>true</implicitSpringDamper>
        </gazebo>
        <gazebo reference="leftgripperjoint">
            <implicitSpringDamper>true</implicitSpringDamper>
        </gazebo>
        <gazebo reference="rightgripperjoint">
            <implicitSpringDamper>true</implicitSpringDamper>
        </gazebo>
    </xacro:macro>
</robot>