<?xml version="1.0" encoding="utf-8"?>
<!-- This URDF was automatically created by SolidWorks to URDF Exporter! Originally created by Stephen Brawner (brawner@gmail.com) 
     Commit Version: 1.6.0-4-g7f85cfe  Build Version: 1.6.7995.38578
     For more information, please see http://wiki.ros.org/sw_urdf_exporter -->
<robot xmlns:xacro="http://www.ros.org/wiki/xacro">
  <xacro:macro name="drivebase" params="mu mu2">
    <link
      name="base_link">
      <inertial>
        <origin
          xyz="0.0 0.0 -0.5"
          rpy="0 0 0" />
        <mass
          value="18.7" />
        <inertia
          ixx="0.5"
          ixy="0.0"
          ixz="0.0"
          iyy="0.62"
          iyz="0.0"
          izz="1.0" />
      </inertial>
      <visual>
        <origin
          xyz="0 0 0"
          rpy="0 0 0" />
        <geometry>
          <mesh
            filename="file://$(find urc_hw_description)/urdf/meshes/base_link.STL" />
        </geometry>
        <material
          name="">
          <color
            rgba="0.792156862745098 0.819607843137255 0.933333333333333 1" />
        </material>
      </visual>
      <collision>
        <origin
          xyz="0 0 0"
          rpy="0 0 0" />
        <geometry>
          <mesh
            filename="file://$(find urc_hw_description)/urdf/meshes/base_link.STL" />
        </geometry>
      </collision>
    </link>
    <link
      name="Left_Leg">
      <inertial>
        <origin
          xyz="0.0 0.0 0.12"
          rpy="0 0 0" />
        <mass
          value="3.2" />
        <inertia
          ixx="0.0"
          ixy="0.0"
          ixz="0.0"
          iyy="0.62"
          iyz="0.0"
          izz="0.62" />
      </inertial>
      <visual>
        <origin
          xyz="0 0 0"
          rpy="0 0 0" />
        <geometry>
          <mesh
            filename="file://$(find urc_hw_description)/urdf/meshes/Left_Leg.STL" />
        </geometry>
        <material
          name="">
          <color
            rgba="0.792156862745098 0.819607843137255 0.933333333333333 1" />
        </material>
      </visual>
      <collision>
        <origin
          xyz="0 0 0"
          rpy="0 0 0" />
        <geometry>
          <mesh
            filename="file://$(find urc_hw_description)/urdf/meshes/Left_Leg.STL" />
        </geometry>
      </collision>
    </link>
    <joint
      name="Left_Leg_Shaft"
      type="revolute">
      <origin
        xyz="0 0.01 0"
        rpy="1.5791 0 0" />
      <parent
        link="base_link" />
      <child
        link="Left_Leg" />
      <axis
        xyz="0 1 0" />
      <limit
        lower="0"
        upper="0"
        effort="0"
        velocity="0" />
      <dynamics damping="0.01" friction="0.01" />
    </joint>
    <link
      name="Front_Left_Wheel">
      <inertial>
        <origin
          xyz="-9.85790539753673E-07 -0.0424756522296364 1.28556895756526E-06"
          rpy="0 0 0" />
        <mass
          value="2.8404147429667" />
        <inertia
          ixx="0.0145900092361804"
          ixy="-9.4552077768867E-09"
          ixz="8.60523625668408E-08"
          iyy="0.0271163761346378"
          iyz="1.22920397171907E-08"
          izz="0.0145900654827055" />
      </inertial>
      <visual>
        <origin
          xyz="0 0 0"
          rpy="0 0 0" />
        <geometry>
          <mesh
            filename="file://$(find urc_hw_description)/urdf/meshes/Front_Left_Wheel.STL" />
        </geometry>
        <material
          name="">
          <color
            rgba="0.792156862745098 0.819607843137255 0.933333333333333 1" />
        </material>
      </visual>
      <collision>
        <origin
          xyz="0 0 0"
          rpy="0 0 0" />
        <geometry>
          <mesh
            filename="file://$(find urc_hw_description)/urdf/meshes/Front_Left_Wheel.STL" />
        </geometry>
      </collision>
      <surface>
        <friction>
          <ode>
            <mu>${mu}</mu>
            <mu2>${mu2}</mu2>
          </ode>
        </friction>
      </surface>
    </link>
    <joint
      name="Front_Left_Shaft"
      type="continuous">
      <origin
        xyz="-0.35884 -0.36484 -0.34252"
        rpy="0 -0.0083213 -1.5708" />
      <parent
        link="Left_Leg" />
      <child
        link="Front_Left_Wheel" />
      <axis
        xyz="0 1 0" />
    </joint>
    <link
      name="Back_Left_Wheel">
      <inertial>
        <origin
          xyz="0.0 0.0 0.0"
          rpy="0 0 0" />
        <mass
          value="1.4" />
        <inertia
          ixx="0.005"
          ixy="0.0"
          ixz="0"
          iyy="0.01"
          iyz="0.0"
          izz="0.005" />
      </inertial>
      <visual>
        <origin
          xyz="0 0 0"
          rpy="0 0 0" />
        <geometry>
          <mesh
            filename="file://$(find urc_hw_description)/urdf/meshes/Back_Left_Wheel.STL" />
        </geometry>
        <material
          name="">
          <color
            rgba="0.792156862745098 0.819607843137255 0.933333333333333 1" />
        </material>
      </visual>
      <collision>
        <origin
          xyz="0 0 0"
          rpy="0 0 0" />
        <geometry>
          <mesh
            filename="file://$(find urc_hw_description)/urdf/meshes/Back_Left_Wheel.STL" />
        </geometry>
      </collision>
      <surface>
        <friction>
          <ode>
            <mu>${mu}</mu>
            <mu2>${mu2}</mu2>
          </ode>
        </friction>
      </surface>
    </link>
    <joint
      name="Back_Left_Shaft"
      type="continuous">
      <origin
        xyz="-0.35884 -0.35931 0.36866"
        rpy="0 -1.3867 -1.5708" />
      <parent
        link="Left_Leg" />
      <child
        link="Back_Left_Wheel" />
      <axis
        xyz="0 1 0" />
    </joint>
    <!-- <link -->
    <!--   name="Differential_Bar"> -->
    <!--   <inertial> -->
    <!--     <origin -->
    <!--       xyz="0.0001696304329344 0.0146364855896726 0.0184524262584146" -->
    <!--       rpy="0 0 0" /> -->
    <!--     <mass -->
    <!--       value="0.8870349519636" /> -->
    <!--     <inertia -->
    <!--       ixx="0.00029545831305288" -->
    <!--       ixy="6.25770619004021E-05" -->
    <!--       ixz="4.35881163876293E-08" -->
    <!--       iyy="0.00652074651602383" -->
    <!--       iyz="-2.01385937443393E-07" -->
    <!--       izz="0.00679287106362345" /> -->
    <!--   </inertial> -->
    <!--   <visual> -->
    <!--     <origin -->
    <!--       xyz="0 0 0" -->
    <!--       rpy="0 0 0" /> -->
    <!--     <geometry> -->
    <!--       <mesh -->
    <!--         filename="file://$(find urc_hw_description)/urdf/meshes/Differential_Bar.STL" /> -->
    <!--     </geometry> -->
    <!--     <material -->
    <!--       name=""> -->
    <!--       <color -->
    <!--         rgba="0.792156862745098 0.819607843137255 0.933333333333333 1" /> -->
    <!--     </material> -->
    <!--   </visual> -->
    <!--   <collision> -->
    <!--     <origin -->
    <!--       xyz="0 0 0" -->
    <!--       rpy="0 0 0" /> -->
    <!--     <geometry> -->
    <!--       <mesh -->
    <!--         filename="file://$(find urc_hw_description)/urdf/meshes/Differential_Bar.STL" /> -->
    <!--     </geometry> -->
    <!--   </collision> -->
    <!-- </link> -->
    <!-- <joint -->
    <!--   name="Differential_Bar_Shaft" -->
    <!--   type="revolute"> -->
    <!--   <origin -->
    <!--     xyz="0 -0.37445 -0.070294" -->
    <!--     rpy="1.5708 0 0" /> -->
    <!--   <parent -->
    <!--     link="base_link" /> -->
    <!--   <child -->
    <!--     link="Differential_Bar" /> -->
    <!--   <axis -->
    <!--     xyz="0 0 1" /> -->
    <!--   <limit -->
    <!--     lower="0" -->
    <!--     upper="0" -->
    <!--     effort="0" -->
    <!--     velocity="0" /> -->
    <!--     <dynamics damping="0.01" friction="0.01" /> -->
    <!-- </joint> -->
    <link
      name="Right_Leg">
      <inertial>
        <origin
          xyz="0.0 0.0 0.12"
          rpy="0 0 0" />
        <mass
          value="3.2" />
        <inertia
          ixx="0.0"
          ixy="0.0"
          ixz="0.0"
          iyy="0.62"
          iyz="0.0"
          izz="0.62" />
      </inertial>
      <visual>
        <origin
          xyz="0 0 0"
          rpy="0 0 0" />
        <geometry>
          <mesh
            filename="file://$(find urc_hw_description)/urdf/meshes/Right_Leg.STL" />
        </geometry>
        <material
          name="">
          <color
            rgba="0.792156862745098 0.819607843137255 0.933333333333333 1" />
        </material>
      </visual>
      <collision>
        <origin
          xyz="0 0 0"
          rpy="0 0 0" />
        <geometry>
          <mesh
            filename="file://$(find urc_hw_description)/urdf/meshes/Right_Leg.STL" />
        </geometry>
      </collision>
    </link>
    <joint
      name="Right_Leg_Shaft"
      type="revolute">
      <origin
        xyz="0 -0.0011403 0.0099997"
        rpy="1.5791 0 0" />
      <parent
        link="base_link" />
      <child
        link="Right_Leg" />
      <axis
        xyz="0 1 0" />
      <limit
        lower="0"
        upper="0"
        effort="0"
        velocity="0" />
        <dynamics damping="0.01" friction="0.01" />
    </joint>
    <link
      name="Front_Right_Wheel">
      <inertial>
        <origin
          xyz="0.0 0.0 0.0"
          rpy="0 0 0" />
        <mass
          value="1.4" />
        <inertia
          ixx="0.005"
          ixy="0.0"
          ixz="0"
          iyy="0.01"
          iyz="0.0"
          izz="0.005" />
      </inertial>
      <visual>
        <origin
          xyz="0 0 0"
          rpy="0 0 0" />
        <geometry>
          <mesh
            filename="file://$(find urc_hw_description)/urdf/meshes/Front_Right_Wheel.STL" />
        </geometry>
        <material
          name="">
          <color
            rgba="0.792156862745098 0.819607843137255 0.933333333333333 1" />
        </material>
      </visual>
      <collision>
        <origin
          xyz="0 0 0"
          rpy="0 0 0" />
        <geometry>
          <mesh
            filename="file://$(find urc_hw_description)/urdf/meshes/Front_Right_Wheel.STL" />
        </geometry>
      </collision>
      <surface>
        <friction>
          <ode>
            <mu>${mu}</mu>
            <mu2>${mu2}</mu2>
          </ode>
        </friction>
      </surface>
    </link>
    <joint
      name="Front_Right_Shaft"
      type="continuous">
      <origin
        xyz="0.35884 -0.37493 -0.35357"
        rpy="0 0.0083213 1.5708" />
      <parent
        link="Right_Leg" />
      <child
        link="Front_Right_Wheel" />
      <axis
        xyz="0 1 0" />
    </joint>
    <link
      name="Back_Right_Wheel">
      <inertial>
        <origin
          xyz="-9.8607342807755E-07 -0.0424756522332874 1.28600934945489E-06"
          rpy="0 0 0" />
        <mass
          value="2.84041474188708" />
        <inertia
          ixx="0.0145900092368819"
          ixy="-9.45447451911223E-09"
          ixz="8.60519025479613E-08"
          iyy="0.0271163761346353"
          iyz="1.22923419163295E-08"
          izz="0.0145900654816172" />
      </inertial>
      <visual>
        <origin
          xyz="0 0 0"
          rpy="0 0 0" />
        <geometry>
          <mesh
            filename="file://$(find urc_hw_description)/urdf/meshes/Back_Right_Wheel.STL" />
        </geometry>
        <material
          name="">
          <color
            rgba="0.792156862745098 0.819607843137255 0.933333333333333 1" />
        </material>
      </visual>
      <collision>
        <origin
          xyz="0 0 0"
          rpy="0 0 0" />
        <geometry>
          <mesh
            filename="file://$(find urc_hw_description)/urdf/meshes/Back_Right_Wheel.STL" />
        </geometry>
      </collision>
      <surface>
        <friction>
          <ode>
            <mu>${mu}</mu>
            <mu2>${mu2}</mu2>
          </ode>
        </friction>
      </surface>
    </link>
    <joint
      name="Back_Right_Shaft"
      type="continuous">
      <origin
        xyz="0.358842224999926 -0.369400178446968 0.357603754666081"
        rpy="0 0.0083213063996962 1.57079632679444" />
      <parent
        link="Right_Leg" />
      <child
        link="Back_Right_Wheel" />
      <axis
        xyz="0 1 0" />
    </joint>

    <gazebo reference="base_link">
      <material>Gazebo/Grey</material>
    </gazebo>
    <gazebo reference="Left_Leg">
      <material>Gazebo/Grey</material>
    </gazebo>
    <gazebo reference="Front_Left_Wheel">
      <material>Gazebo/Black</material>
    </gazebo>
    <gazebo reference="Back_Left_Wheel">
      <material>Gazebo/Black</material>
    </gazebo>
    <gazebo reference="Differential_Bar">
      <material>Gazebo/Grey</material>
    </gazebo>
    <gazebo reference="Right_Leg">
      <material>Gazebo/Grey</material>
    </gazebo>
    <gazebo reference="Front_Right_Wheel">
      <material>Gazebo/Black</material>
    </gazebo>
    <gazebo reference="Back_Right_Wheel">
      <material>Gazebo/Black</material>
    </gazebo>
  </xacro:macro>
</robot>
