<?xml version="1.0" ?>
<!-- =================================================================================== -->
<!-- |    This document was autogenerated by xacro from walli.xacro                    | -->
<!-- |    EDITING THIS FILE BY HAND IS NOT RECOMMENDED                                 | -->
<!-- =================================================================================== -->
<robot name="walli">
  <!-- body_length is measured along the x axis, body_width
       along the y axis, and body_height along the z axis. -->
  <material name="body_mat">
    <color rgba="0.5 0.5 0.5 1"/>
  </material>
  <material name="tire_mat">
    <color rgba="0 0 0 1"/>
  </material>
  <!-- IMU -->
  <link name="imu_link"/>
  <joint name="imu_joint" type="fixed">
    <origin xyz="0.14 0.0 0.22"/>
    <parent link="base_link"/>
    <child link="imu_link"/>
  </joint>
  <gazebo reference="imu_link">
    <sensor name="imu_sensor" type="imu">
      <plugin filename="libgazebo_ros_imu_sensor.so" name="imu_plugin">
        <ros>
          <namespace>/imu</namespace>
          <remapping>~/out:=data</remapping>
        </ros>
        <initial_orientation_as_reference>false</initial_orientation_as_reference>
      </plugin>
      <always_on>true</always_on>
      <update_rate>100</update_rate>
      <visualize>true</visualize>
      <imu>
        <angular_velocity>
          <x>
            <noise type="gaussian">
              <mean>0.0</mean>
              <stddev>2e-4</stddev>
              <bias_mean>0.0</bias_mean>
              <bias_stddev>0.0</bias_stddev>
            </noise>
          </x>
          <y>
            <noise type="gaussian">
              <mean>0.0</mean>
              <stddev>2e-4</stddev>
              <bias_mean>0.0</bias_mean>
              <bias_stddev>0.0</bias_stddev>
            </noise>
          </y>
          <z>
            <noise type="gaussian">
              <mean>0.0</mean>
              <stddev>2e-4</stddev>
              <bias_mean>0.0</bias_mean>
              <bias_stddev>0.0</bias_stddev>
            </noise>
          </z>
        </angular_velocity>
        <linear_acceleration>
          <x>
            <noise type="gaussian">
              <mean>0.0</mean>
              <stddev>1.7e-2</stddev>
              <bias_mean>0.0</bias_mean>
              <bias_stddev>0.0</bias_stddev>
            </noise>
          </x>
          <y>
            <noise type="gaussian">
              <mean>0.0</mean>
              <stddev>1.7e-2</stddev>
              <bias_mean>0.0</bias_mean>
              <bias_stddev>0.0</bias_stddev>
            </noise>
          </y>
          <z>
            <noise type="gaussian">
              <mean>0.0</mean>
              <stddev>1.7e-2</stddev>
              <bias_mean>0.0</bias_mean>
              <bias_stddev>0.0</bias_stddev>
            </noise>
          </z>
        </linear_acceleration>
      </imu>
    </sensor>
  </gazebo>
  <!-- GPS -->
  <link name="gps_link">
    <visual>
      <geometry>
        <box size="0.05 0.05 0.05"/>
      </geometry>
    </visual>
    <collision>
      <geometry>
        <box size="0.05 0.05 0.05"/>
      </geometry>
    </collision>
    <inertial>
      <origin rpy="1.5707963267948966 0 1.5707963267948966" xyz="0 0 0"/>
      <mass value="0.1"/>
      <inertia ixx="0.0001666666666666667" ixy="0.0" ixz="0.0" iyy="0.0001666666666666667" iyz="0.0" izz="0.0001666666666666667"/>
    </inertial>
  </link>
  <joint name="gps_joint" type="fixed">
    <axis xyz="1 0 0"/>
    <origin xyz="-0.39 -0.27 0.34"/>
    <parent link="base_link"/>
    <child link="gps_link"/>
  </joint>
  <gazebo reference="gps">
    <sensor name="gps" type="gps">
      <plugin filename="libgazebo_ros_gps_sensor.so" name="gps_plugin">
        <ros>
          <namespace>/gps</namespace>
          <remapping>~/out:=data_raw</remapping>
        </ros>
        <frame_name>gps_link</frame_name>
      </plugin>
      <always_on>true</always_on>
      <updateRate>30</updateRate>
    </sensor>
  </gazebo>
  <!-- LIDAR -->
  <link name="lidar_link2">
    <inertial>
      <origin rpy="0 0 0" xyz="0 0 0"/>
      <mass value="0.125"/>
      <inertia ixx="0.001" ixy="0" ixz="0" iyy="0.001" iyz="0" izz="0.001"/>
    </inertial>
    <collision>
      <origin rpy="0 0 0" xyz="0 0 0"/>
      <geometry>
        <cylinder length="0.055" radius="0.0508"/>
      </geometry>
    </collision>
    <visual>
      <origin rpy="0 0 0" xyz="0 0 0"/>
      <geometry>
        <cylinder length="0.055" radius="0.0508"/>
      </geometry>
    </visual>
  </link>
  <joint name="lidar_joint" type="fixed">
    <parent link="base_link"/>
    <child link="lidar_link2"/>
    <origin rpy="3.14159265358 0 0" xyz="0.1778 0.0 0.254"/>
  </joint>
  <!--<gazebo reference="lidar_link">
    <sensor name="lidar" type="ray">
      <always_on>true</always_on>
      <visualize>true</visualize>
      <update_rate>5</update_rate>
      <ray>
        <scan>
          <horizontal>
            <samples>360</samples>
            <resolution>1.000000</resolution>
            <min_angle>0.000000</min_angle>
            <max_angle>6.280000</max_angle>
          </horizontal>
        </scan>
        <range>
          <min>0.12</min>
          <max>3.5</max>
          <resolution>0.015000</resolution>
        </range>
        <noise>
          <type>gaussian</type>
          <mean>0.0</mean>
          <stddev>0.01</stddev>
        </noise>
      </ray>
      <plugin name="scan" filename="libgazebo_ros_ray_sensor.so">
        <ros>
          <remapping>~/out:=scan</remapping>
        </ros>
        <output_type>sensor_msgs/LaserScan</output_type>
        <frame_name>lidar_link</frame_name>
      </plugin>
    </sensor>
  </gazebo> -->
  <link name="cam/center">
    <visual>
      <geometry>
        <box size="0.01 0.01 0.01"/>
      </geometry>
    </visual>
    <collision>
      <geometry>
        <box size="0.01 0.01 0.01"/>
      </geometry>
    </collision>
    <inertial>
      <origin rpy="1.5707963267948966 0 1.5707963267948966" xyz="0 0 0"/>
      <mass value="0.01"/>
      <inertia ixx="1.6666666666666668e-07" ixy="0.0" ixz="0.0" iyy="1.6666666666666668e-07" iyz="0.0" izz="1.6666666666666668e-07"/>
    </inertial>
  </link>
  <joint name="center_cam_joint" type="fixed">
    <axis xyz="1 0 0"/>
    <!-- Camera Orientation-->
    <origin rpy="0 0 -0.14" xyz="0.1 0 0"/>
    <parent link="base_link"/>
    <child link="cam/center"/>
  </joint>
  <gazebo reference="cam/center">
    <sensor name="center_sensor" type="camera">
      <plugin filename="libgazebo_ros_camera.so" name="center_sensor">
        <ros>
          <namespace>/image</namespace>
          <remapping>~/image_raw:=center_img</remapping>
          <remapping>~/camera_info:=center_camera_info</remapping>
        </ros>
        <initial_orientation_as_reference>false</initial_orientation_as_reference>
        <camera_name>center_camera</camera_name>
        <frame_name>center_tf</frame_name>
        <hack_baseline>0.07</hack_baseline>
      </plugin>
      <always_on>true</always_on>
      <update_rate>100</update_rate>
      <visualize>true</visualize>
      <camera name="cam/center">
        <horizontal_fov>1.3962634</horizontal_fov>
        <image>
          <width>800</width>
          <height>800</height>
          <format>R8G8B8</format>
        </image>
        <clip>
          <near>0.02</near>
          <far>300</far>
        </clip>
        <noise>
          <type>gaussian</type>
          <mean>0</mean>
          <stddev>0.007</stddev>
        </noise>
      </camera>
    </sensor>
  </gazebo>
  <link name="cam/left">
    <visual>
      <geometry>
        <box size="0.01 0.01 0.01"/>
      </geometry>
    </visual>
    <collision>
      <geometry>
        <box size="0.01 0.01 0.01"/>
      </geometry>
    </collision>
    <inertial>
      <origin rpy="1.5707963267948966 0 1.5707963267948966" xyz="0 0 0"/>
      <mass value="0.01"/>
      <inertia ixx="1.6666666666666668e-07" ixy="0.0" ixz="0.0" iyy="1.6666666666666668e-07" iyz="0.0" izz="1.6666666666666668e-07"/>
    </inertial>
  </link>
  <joint name="left_cam_joint" type="fixed">
    <axis xyz="1 0 0"/>
    <!-- Camera Orientation-->
    <origin rpy="0 0 1.5" xyz="0 0.3 0"/>
    <parent link="base_link"/>
    <child link="cam/left"/>
  </joint>
  <gazebo reference="cam/left">
    <sensor name="left_sensor" type="camera">
      <plugin filename="libgazebo_ros_camera.so" name="left_sensor">
        <ros>
          <namespace>/image</namespace>
          <remapping>~/image_raw:=left_img</remapping>
          <remapping>~/camera_info:=left_camera_info</remapping>
        </ros>
        <initial_orientation_as_reference>false</initial_orientation_as_reference>
        <camera_name>left_camera</camera_name>
        <frame_name>left_tf</frame_name>
        <hack_baseline>0.07</hack_baseline>
      </plugin>
      <always_on>true</always_on>
      <update_rate>100</update_rate>
      <visualize>true</visualize>
      <camera name="cam/left">
        <horizontal_fov>1.3962634</horizontal_fov>
        <image>
          <width>800</width>
          <height>800</height>
          <format>R8G8B8</format>
        </image>
        <clip>
          <near>0.02</near>
          <far>300</far>
        </clip>
        <noise>
          <type>gaussian</type>
          <mean>0</mean>
          <stddev>0.007</stddev>
        </noise>
      </camera>
    </sensor>
  </gazebo>
  <link name="cam/right">
    <visual>
      <geometry>
        <box size="0.01 0.01 0.01"/>
      </geometry>
    </visual>
    <collision>
      <geometry>
        <box size="0.01 0.01 0.01"/>
      </geometry>
    </collision>
    <inertial>
      <origin rpy="1.5707963267948966 0 1.5707963267948966" xyz="0 0 0"/>
      <mass value="0.01"/>
      <inertia ixx="1.6666666666666668e-07" ixy="0.0" ixz="0.0" iyy="1.6666666666666668e-07" iyz="0.0" izz="1.6666666666666668e-07"/>
    </inertial>
  </link>
  <joint name="right_cam_joint" type="fixed">
    <axis xyz="1 0 0"/>
    <!-- Camera Orientation-->
    <origin rpy="0 0 -1.5" xyz="0 -0.3 0"/>
    <parent link="base_link"/>
    <child link="cam/right"/>
  </joint>
  <gazebo reference="cam/right">
    <sensor name="right_sensor" type="camera">
      <plugin filename="libgazebo_ros_camera.so" name="right_sensor">
        <ros>
          <namespace>/image</namespace>
          <remapping>~/image_raw:=right_img</remapping>
          <remapping>~/camera_info:=right_camera_info</remapping>
        </ros>
        <initial_orientation_as_reference>false</initial_orientation_as_reference>
        <camera_name>right_camera</camera_name>
        <frame_name>right_tf</frame_name>
        <hack_baseline>0.07</hack_baseline>
      </plugin>
      <always_on>true</always_on>
      <update_rate>100</update_rate>
      <visualize>true</visualize>
      <camera name="cam/right">
        <horizontal_fov>1.3962634</horizontal_fov>
        <image>
          <width>800</width>
          <height>800</height>
          <format>R8G8B8</format>
        </image>
        <clip>
          <near>0.02</near>
          <far>300</far>
        </clip>
        <noise>
          <type>gaussian</type>
          <mean>0</mean>
          <stddev>0.007</stddev>
        </noise>
      </camera>
    </sensor>
  </gazebo>
  <!-- Depth Camera -->
  <link name="camera_link">
    <visual>
      <origin rpy="0 0 0" xyz="0 0 0"/>
      <geometry>
        <box size="0.015 0.130 0.022"/>
      </geometry>
    </visual>
    <collision>
      <origin rpy="0 0 0" xyz="0 0 0"/>
      <geometry>
        <box size="0.015 0.130 0.022"/>
      </geometry>
    </collision>
    <inertial>
      <origin rpy="0 0 0" xyz="0 0 0"/>
      <mass value="0.035"/>
      <inertia ixx="0.001" ixy="0" ixz="0" iyy="0.001" iyz="0" izz="0.001"/>
    </inertial>
  </link>
  <joint name="camera_joint" type="fixed">
    <parent link="base_link"/>
    <child link="camera_link"/>
    <origin rpy="0 0 0" xyz="0.1 0 0.03"/>
  </joint>
  <link name="camera_depth_frame"/>
  <joint name="camera_depth_joint" type="fixed">
    <origin rpy="-1.5707963267948966 0 -1.5707963267948966" xyz="0 0 0"/>
    <parent link="camera_link"/>
    <child link="camera_depth_frame"/>
  </joint>
  <gazebo reference="camera_link">
    <sensor name="depth_camera" type="depth">
      <visualize>true</visualize>
      <update_rate>30.0</update_rate>
      <camera name="camera">
        <horizontal_fov>1.51844</horizontal_fov>
        <image>
          <width>640</width>
          <height>360</height>
          <format>R8G8B8</format>
        </image>
        <clip>
          <near>0.05</near>
          <far>3</far>
        </clip>
      </camera>
      <plugin filename="libgazebo_ros_camera.so" name="depth_camera_controller">
        <baseline>0.2</baseline>
        <alwaysOn>true</alwaysOn>
        <updateRate>0.0</updateRate>
        <frame_name>camera_depth_frame</frame_name>
        <pointCloudCutoff>0.5</pointCloudCutoff>
        <pointCloudCutoffMax>3.0</pointCloudCutoffMax>
        <distortionK1>0</distortionK1>
        <distortionK2>0</distortionK2>
        <distortionK3>0</distortionK3>
        <distortionT1>0</distortionT1>
        <distortionT2>0</distortionT2>
        <CxPrime>0</CxPrime>
        <Cx>0</Cx>
        <Cy>0</Cy>
        <focalLength>0</focalLength>
        <hackBaseline>0</hackBaseline>
      </plugin>
    </sensor>
  </gazebo>
  <gazebo>
    <sensor name="imu" type="imu">
      <always_on>true</always_on>
      <update_rate>30</update_rate>
      <plugin filename="libgazebo_ros_imu_sensor.so" name="imu">
        <ros>
          <namespace>/imu</namespace>
          <argument>~/out:=data</argument>
        </ros>
        <frame_name>imu</frame_name>
      </plugin>
    </sensor>
    <plugin filename="libgazebo_ros_p3d.so" name="gazebo_ros_p3d">
      <alwaysOn>true</alwaysOn>
      <update_rate>30.0</update_rate>
      <ros>
        <namespace>/ground_truth</namespace>
        <remapping>odom:=state_raw</remapping>
      </ros>
      <body_name>base_link</body_name>
      <frame_name>world</frame_name>
      <xyz_offset>0 0 0</xyz_offset>
      <rpy_offset>0.0 0.0 0.0</rpy_offset>
      <gaussian_noise>0.00</gaussian_noise>
    </plugin>
  </gazebo>
  <link name="base_link">
    <inertial>
      <origin rpy="0 0 0" xyz="-0.22771 0.0020794 0.13424"/>
      <mass value="1.584994"/>
      <inertia ixx="0.017201" ixy="-2.0986E-11" ixz="5.8899E-06" iyy="0.0028906" iyz="5.0336E-07" izz="0.019124"/>
    </inertial>
    <visual>
      <origin rpy="0 0 0" xyz="0 0 0"/>
      <geometry>
        <mesh filename="file:///home/rover_ws/install/urc_hw_description/share/urc_hw_description/urdf/meshes/visual/base_link.STL"/>
      </geometry>
    </visual>
    <collision>
      <origin rpy="0 0 0" xyz="0 0 0"/>
      <geometry>
        <mesh filename="file:///home/rover_ws/install/urc_hw_description/share/urc_hw_description/urdf/meshes/collision/base_link_collision.STL"/>
      </geometry>
    </collision>
  </link>
  <!-- ROCKERS -->
  <link name="rightrocker">
    <inertial>
      <origin rpy="0 0 0" xyz="0.062687 0.034616 -0.016048"/>
      <mass value="1.387336"/>
      <inertia ixx="0.002956" ixy="-0.000001489324" ixz="-0.000008103407" iyy="0.02924" iyz="0.00007112" izz="0.02832"/>
    </inertial>
    <visual>
      <origin rpy="0 0 0" xyz="0 0 0"/>
      <geometry>
        <mesh filename="file:///home/rover_ws/install/urc_hw_description/share/urc_hw_description/urdf/meshes/visual/rightrocker.STL"/>
      </geometry>
    </visual>
    <collision>
      <origin rpy="0 0 0" xyz="0 0 0"/>
      <geometry>
        <mesh filename="file:///home/rover_ws/install/urc_hw_description/share/urc_hw_description/urdf/meshes/collision/rightrocker_collision.STL"/>
      </geometry>
    </collision>
  </link>
  <joint name="rightrockerjoint" type="revolute">
    <origin rpy="0 0 0" xyz="-0.194 -0.33715 0.080295"/>
    <parent link="base_link"/>
    <child link="rightrocker"/>
    <axis xyz="0 1 0"/>
    <limit effort="0.0" lower="-0.24" upper="0.24" velocity="100.0"/>
    <dynamics damping="0.1" friction="1.0"/>
  </joint>
  <link name="leftrocker">
    <inertial>
      <origin rpy="0 0 0" xyz="0.065435 -0.034981 -0.01685"/>
      <mass value="1.387336"/>
      <inertia ixx="0.002956" ixy="-0.000001489324" ixz="-0.000008103407" iyy="0.02924" iyz="0.00007112" izz="0.02832"/>
    </inertial>
    <visual>
      <origin rpy="0 0 0" xyz="0 0 0"/>
      <geometry>
        <mesh filename="file:///home/rover_ws/install/urc_hw_description/share/urc_hw_description/urdf/meshes/visual/leftrocker.STL"/>
      </geometry>
    </visual>
    <collision>
      <origin rpy="0 0 0" xyz="0 0 0"/>
      <geometry>
        <mesh filename="file:///home/rover_ws/install/urc_hw_description/share/urc_hw_description/urdf/meshes/collision/leftrocker_collision.STL"/>
      </geometry>
    </collision>
  </link>
  <joint name="leftrockerjoint" type="revolute">
    <origin rpy="0 0 0" xyz="-0.19241 0.33715 0.080257"/>
    <parent link="base_link"/>
    <child link="leftrocker"/>
    <axis xyz="0 1 0"/>
    <limit effort="0.0" lower="-0.24" upper="0.24" velocity="100.0"/>
    <dynamics damping="0.1" friction="1.0"/>
  </joint>
  <!-- BOGIES -->
  <link name="rightbogie">
    <inertial>
      <origin rpy="0 0 0" xyz="-6.8787E-09 0.032385 -0.015429"/>
      <mass value="0.66758"/>
      <inertia ixx="0.0019756" ixy="-5.9804E-10" ixz="9.4624E-11" iyy="0.0044836" iyz="2.6509E-13" izz="0.003846"/>
    </inertial>
    <visual>
      <origin rpy="0 0 0" xyz="0 0 0"/>
      <geometry>
        <mesh filename="file:///home/rover_ws/install/urc_hw_description/share/urc_hw_description/urdf/meshes/visual/rightbogie.STL"/>
      </geometry>
    </visual>
    <collision>
      <origin rpy="0 0 0" xyz="0 0 0"/>
      <geometry>
        <mesh filename="file:///home/rover_ws/install/urc_hw_description/share/urc_hw_description/urdf/meshes/collision/rightbogie_collision.STL"/>
      </geometry>
    </collision>
  </link>
  <joint name="rightbogiejoint" type="revolute">
    <origin rpy="0 0 0" xyz="0.24177 -0.00254 -0.074203"/>
    <parent link="rightrocker"/>
    <child link="rightbogie"/>
    <axis xyz="0 1 0"/>
    <limit effort="0.0" lower="-0.24" upper="0.24" velocity="100.0"/>
    <dynamics damping="0.1" friction="1.0"/>
  </joint>
  <link name="leftbogie">
    <inertial>
      <origin rpy="0 0 0" xyz="-6.8787E-09 -0.032385 -0.015429"/>
      <mass value="0.66758"/>
      <inertia ixx="0.0019756" ixy="-5.9804E-10" ixz="9.4624E-11" iyy="0.0044836" iyz="2.6509E-13" izz="0.003846"/>
    </inertial>
    <visual>
      <origin rpy="0 0 0" xyz="0 0 0"/>
      <geometry>
        <mesh filename="file:///home/rover_ws/install/urc_hw_description/share/urc_hw_description/urdf/meshes/visual/leftbogie.STL"/>
      </geometry>
    </visual>
    <collision>
      <origin rpy="0 0 0" xyz="0 0 0"/>
      <geometry>
        <mesh filename="file:///home/rover_ws/install/urc_hw_description/share/urc_hw_description/urdf/meshes/collision/leftbogie_collision.STL"/>
      </geometry>
    </collision>
  </link>
  <joint name="leftbogiejoint" type="revolute">
    <origin rpy="0 0 0" xyz="0.24182 0.00254 -0.073984"/>
    <parent link="leftrocker"/>
    <child link="leftbogie"/>
    <axis xyz="0 1 0"/>
    <limit effort="0.0" lower="-0.24" upper="0.24" velocity="100.0"/>
    <dynamics damping="0.1" friction="1.0"/>
  </joint>
  <!-- WHEELS -->
  <link name="right_rear_wheel">
    <inertial>
      <origin rpy="0 0 0" xyz="0 0 0"/>
      <mass value="0.283642"/>
      <inertia ixx="0.000391" ixy="0.00000123962" ixz="5.52582e-7" iyy="0.0004716" iyz="-0.000002082042" izz="0.000391"/>
    </inertial>
    <visual>
      <origin rpy="1.5707963267948966 0 0" xyz="0 0 0"/>
      <geometry>
        <cylinder length="0.08" radius="0.1"/>
      </geometry>
    </visual>
    <collision>
      <origin rpy="1.5707963267948966 0 0" xyz="0 0 0"/>
      <geometry>
        <cylinder length="0.08" radius="0.1"/>
      </geometry>
    </collision>
  </link>
  <joint name="right_rear_wheel_joint" type="continuous">
    <origin rpy="0 0 0" xyz="-0.36316 -0.04 -0.19158"/>
    <parent link="rightrocker"/>
    <child link="right_rear_wheel"/>
    <axis xyz="0 1 0"/>
    <dynamics damping="0.1" friction="0.3125"/>
  </joint>
  <link name="right_front_wheel">
    <inertial>
      <origin rpy="0 0 0" xyz="0 0 0"/>
      <mass value="0.283642"/>
      <inertia ixx="0.000391" ixy="0.00000123962" ixz="5.52582e-7" iyy="0.0004716" iyz="-0.000002082042" izz="0.000391"/>
    </inertial>
    <visual>
      <origin rpy="1.5707963267948966 0 0" xyz="0 0 0"/>
      <geometry>
        <cylinder length="0.08" radius="0.1"/>
      </geometry>
    </visual>
    <collision>
      <origin rpy="1.5707963267948966 0 0" xyz="0 0 0"/>
      <geometry>
        <cylinder length="0.08" radius="0.1"/>
      </geometry>
    </collision>
  </link>
  <joint name="right_front_wheel_joint" type="continuous">
    <origin rpy="0 0 0" xyz="0.20139 -0.04 -0.11671"/>
    <parent link="rightbogie"/>
    <child link="right_front_wheel"/>
    <axis xyz="0 1 0"/>
    <dynamics damping="0.1" friction="0.3125"/>
  </joint>
  <link name="right_center_wheel">
    <inertial>
      <origin rpy="0 0 0" xyz="0 0 0"/>
      <mass value="0.283642"/>
      <inertia ixx="0.000391" ixy="0.00000123962" ixz="5.52582e-7" iyy="0.0004716" iyz="-0.000002082042" izz="0.000391"/>
    </inertial>
    <visual>
      <origin rpy="1.5707963267948966 0 0" xyz="0 0 0"/>
      <geometry>
        <cylinder length="0.08" radius="0.1"/>
      </geometry>
    </visual>
    <collision>
      <origin rpy="1.5707963267948966 0 0" xyz="0 0 0"/>
      <geometry>
        <cylinder length="0.08" radius="0.1"/>
      </geometry>
    </collision>
  </link>
  <joint name="right_center_wheel_joint" type="continuous">
    <origin rpy="0 0 0" xyz="-0.20177 -0.04 -0.11606"/>
    <parent link="rightbogie"/>
    <child link="right_center_wheel"/>
    <axis xyz="0 1 0"/>
    <dynamics damping="0.1" friction="0.3125"/>
  </joint>
  <link name="left_rear_wheel">
    <inertial>
      <origin rpy="0 0 0" xyz="0 0 0"/>
      <mass value="0.283642"/>
      <inertia ixx="0.000391" ixy="0.00000123962" ixz="5.52582e-7" iyy="0.0004716" iyz="-0.000002082042" izz="0.000391"/>
    </inertial>
    <visual>
      <origin rpy="1.5707963267948966 0 0" xyz="0 0 0"/>
      <geometry>
        <cylinder length="0.08" radius="0.1"/>
      </geometry>
    </visual>
    <collision>
      <origin rpy="1.5707963267948966 0 0" xyz="0 0 0"/>
      <geometry>
        <cylinder length="0.08" radius="0.1"/>
      </geometry>
    </collision>
  </link>
  <joint name="left_rear_wheel_joint" type="continuous">
    <origin rpy="0 0 0" xyz="-0.36266 0.04 -0.19248"/>
    <parent link="leftrocker"/>
    <child link="left_rear_wheel"/>
    <axis xyz="0 1 0"/>
    <dynamics damping="0.1" friction="0.3125"/>
  </joint>
  <link name="left_front_wheel">
    <inertial>
      <origin rpy="0 0 0" xyz="0 0 0"/>
      <mass value="0.283642"/>
      <inertia ixx="0.000391" ixy="0.00000123962" ixz="5.52582e-7" iyy="0.0004716" iyz="-0.000002082042" izz="0.000391"/>
    </inertial>
    <visual>
      <origin rpy="1.5707963267948966 0 0" xyz="0 0 0"/>
      <geometry>
        <cylinder length="0.08" radius="0.1"/>
      </geometry>
    </visual>
    <collision>
      <origin rpy="1.5707963267948966 0 0" xyz="0 0 0"/>
      <geometry>
        <cylinder length="0.08" radius="0.1"/>
      </geometry>
    </collision>
  </link>
  <joint name="left_front_wheel_joint" type="continuous">
    <origin rpy="0 0 0" xyz="0.20177 0.04 -0.11606"/>
    <parent link="leftbogie"/>
    <child link="left_front_wheel"/>
    <axis xyz="0 1 0"/>
    <dynamics damping="0.1" friction="0.3125"/>
  </joint>
  <link name="left_center_wheel">
    <inertial>
      <origin rpy="0 0 0" xyz="0 0 0"/>
      <mass value="0.283642"/>
      <inertia ixx="0.000391" ixy="0.00000123962" ixz="5.52582e-7" iyy="0.0004716" iyz="-0.000002082042" izz="0.000391"/>
    </inertial>
    <visual>
      <origin rpy="1.5707963267948966 0 0" xyz="0 0 0"/>
      <geometry>
        <cylinder length="0.08" radius="0.1"/>
      </geometry>
    </visual>
    <collision>
      <origin rpy="1.5707963267948966 0 0" xyz="0 0 0"/>
      <geometry>
        <cylinder length="0.08" radius="0.1"/>
      </geometry>
    </collision>
  </link>
  <joint name="left_center_wheel_joint" type="continuous">
    <origin rpy="0 0 0" xyz="-0.20139 0.04 -0.11671"/>
    <parent link="leftbogie"/>
    <child link="left_center_wheel"/>
    <axis xyz="0 1 0"/>
    <dynamics damping="0.1" friction="0.3125"/>
  </joint>
  <gazebo reference="base_link">
    <material>Gazebo/Grey</material>
  </gazebo>
  <gazebo reference="rightrocker">
    <material>Gazebo/Grey</material>
  </gazebo>
  <gazebo reference="rightbogie">
    <material>Gazebo/Grey</material>
  </gazebo>
  <gazebo reference="leftrocker">
    <material>Gazebo/Grey</material>
  </gazebo>
  <gazebo reference="leftbogie">
    <material>Gazebo/Grey</material>
  </gazebo>
  <gazebo reference="right_rear_wheel">
    <material>Gazebo/Black</material>
    <kp>1e6</kp>
    <kd>100.0</kd>
    <mu1>1.0</mu1>
    <mu2>0.25</mu2>
    <fdir1>1 0 0</fdir1>
    <minDepth>0.003</minDepth>
  </gazebo>
  <gazebo reference="right_front_wheel">
    <material>Gazebo/Black</material>
    <kp>1e6</kp>
    <kd>100.0</kd>
    <mu1>1.0</mu1>
    <mu2>0.25</mu2>
    <fdir1>1 0 0</fdir1>
    <minDepth>0.003</minDepth>
  </gazebo>
  <gazebo reference="right_center_wheel">
    <material>Gazebo/Black</material>
    <kp>1e6</kp>
    <kd>100.0</kd>
    <mu1>1.0</mu1>
    <mu2>0.25</mu2>
    <fdir1>1 0 0</fdir1>
    <minDepth>0.003</minDepth>
  </gazebo>
  <gazebo reference="left_rear_wheel">
    <material>Gazebo/Black</material>
    <kp>1e6</kp>
    <kd>100.0</kd>
    <mu1>1.0</mu1>
    <mu2>0.25</mu2>
    <fdir1>1 0 0</fdir1>
    <minDepth>0.003</minDepth>
  </gazebo>
  <gazebo reference="left_front_wheel">
    <material>Gazebo/Black</material>
    <kp>1e6</kp>
    <kd>100.0</kd>
    <mu1>1.0</mu1>
    <mu2>0.25</mu2>
    <fdir1>1 0 0</fdir1>
    <minDepth>0.003</minDepth>
  </gazebo>
  <gazebo reference="left_center_wheel">
    <material>Gazebo/Black</material>
    <kp>1e6</kp>
    <kd>100.0</kd>
    <mu1>1.0</mu1>
    <mu2>0.25</mu2>
    <fdir1>1 0 0</fdir1>
    <minDepth>0.003</minDepth>
  </gazebo>
  <ros2_control name="GazeboSystem" type="system">
    <hardware>
      <plugin>gazebo_ros2_control/GazeboSystem</plugin>
    </hardware>
    <joint name="leftbogiejoint">
      <state_interface name="velocity"/>
      <state_interface name="position"/>
    </joint>
    <joint name="leftrockerjoint">
      <state_interface name="velocity"/>
      <state_interface name="position"/>
    </joint>
    <joint name="rightbogiejoint">
      <state_interface name="velocity"/>
      <state_interface name="position"/>
    </joint>
    <joint name="rightrockerjoint">
      <state_interface name="velocity"/>
      <state_interface name="position"/>
    </joint>
    <joint name="left_front_wheel_joint">
      <command_interface name="velocity">
        <param name="min">-0.05</param>
        <param name="max">0.05</param>
      </command_interface>
      <state_interface name="velocity"/>
      <state_interface name="position"/>
    </joint>
    <joint name="right_front_wheel_joint">
      <command_interface name="velocity">
        <param name="min">-0.05</param>
        <param name="max">0.05</param>
      </command_interface>
      <state_interface name="velocity"/>
      <state_interface name="position"/>
    </joint>
    <joint name="left_center_wheel_joint">
      <command_interface name="velocity">
        <param name="min">-0.05</param>
        <param name="max">0.05</param>
      </command_interface>
      <state_interface name="velocity"/>
      <state_interface name="position"/>
    </joint>
    <joint name="right_center_wheel_joint">
      <command_interface name="velocity">
        <param name="min">-0.05</param>
        <param name="max">0.05</param>
      </command_interface>
      <state_interface name="velocity"/>
      <state_interface name="position"/>
    </joint>
    <joint name="left_rear_wheel_joint">
      <command_interface name="velocity">
        <param name="min">-0.05</param>
        <param name="max">0.05</param>
      </command_interface>
      <state_interface name="velocity"/>
      <state_interface name="position"/>
    </joint>
    <joint name="right_rear_wheel_joint">
      <command_interface name="velocity">
        <param name="min">-0.05</param>
        <param name="max">0.05</param>
      </command_interface>
      <state_interface name="velocity"/>
      <state_interface name="position"/>
    </joint>
  </ros2_control>
  <gazebo>
    <plugin filename="libgazebo_ros2_control.so" name="gazebo_ros2_control">
      <parameters>/home/rover_ws/install/urc_bringup/share/urc_bringup/config/controller_config.yaml</parameters>
    </plugin>
  </gazebo>
</robot>
