<?xml version="1.0" encoding="utf-8"?>
<!-- This URDF was automatically created by SolidWorks to URDF Exporter! Originally created by Stephen Brawner (brawner@gmail.com) 
     Commit Version: 1.6.0-4-g7f85cfe  Build Version: 1.6.7995.38578
     For more information, please see http://wiki.ros.org/sw_urdf_exporter -->
<robot xmlns:xacro="http://www.ros.org/wiki/xacro">
  <xacro:macro name="drivebase" params="mu mu2">
    <link
      name="base_link">
      <inertial>
        <origin
          xyz="-0.014317225327403 0.0104296335321108 0.153421389255203"
          rpy="0 0 0" />
        <mass
          value="4.16872664819669" />
        <inertia
          ixx="0.0133014161912341"
          ixy="9.61058451240803E-06"
          ixz="3.78220834652181E-09"
          iyy="0.0282864040971226"
          iyz="-5.32294329059233E-06"
          izz="0.0262313272124921" />
      </inertial>
      <visual>
        <origin
          xyz="0 0 0"
          rpy="0 0 0" />
        <geometry>
          <mesh
            filename="file://$(find urc_hw_description)/urdf/meshes/base_link.STL" />
        </geometry>
        <material
          name="">
          <color
            rgba="0.792156862745098 0.819607843137255 0.933333333333333 1" />
        </material>
      </visual>
      <collision>
        <origin
          xyz="0 0 0"
          rpy="0 0 0" />
        <geometry>
          <mesh
            filename="file://$(find urc_hw_description)/urdf/meshes/base_link.STL" />
        </geometry>
      </collision>
    </link>
    <link
      name="Left_Leg">
      <inertial>
        <origin
          xyz="-0.314720519412685 -0.267228491093624 0.0144844412176535"
          rpy="0 0 0" />
        <mass
          value="1.51922550428194" />
        <inertia
          ixx="0.0172747101435764"
          ixy="1.95090448894846E-06"
          ixz="2.77456502210212E-08"
          iyy="0.016672008092978"
          iyz="-0.000130959848654314"
          izz="0.00134369269865275" />
      </inertial>
      <visual>
        <origin
          xyz="0 0 0"
          rpy="0 0 0" />
        <geometry>
          <mesh
            filename="file://$(find urc_hw_description)/urdf/meshes/Left_Leg.STL" />
        </geometry>
        <material
          name="">
          <color
            rgba="0.792156862745098 0.819607843137255 0.933333333333333 1" />
        </material>
      </visual>
      <collision>
        <origin
          xyz="0 0 0"
          rpy="0 0 0" />
        <geometry>
          <mesh
            filename="file://$(find urc_hw_description)/urdf/meshes/Left_Leg.STL" />
        </geometry>
      </collision>
    </link>
    <joint
      name="Left_Leg_Shaft"
      type="revolute">
      <origin
        xyz="0 0.01 0"
        rpy="1.5791 0 0" />
      <parent
        link="base_link" />
      <child
        link="Left_Leg" />
      <axis
        xyz="0 0 0" />
      <limit
        lower="0"
        upper="0"
        effort="0"
        velocity="0" />
      <dynamics damping="0.01" friction="0.01" />
    </joint>
    <link
      name="Front_Left_Wheel">
      <inertial>
        <origin
          xyz="-9.85643131612424E-07 -0.0424756514469604 1.28618891753751E-06"
          rpy="0 0 0" />
        <mass
          value="1.13616610202435" />
        <inertia
          ixx="0.00583600145685734"
          ixy="-3.78138840894905E-09"
          ixz="3.44212174951375E-08"
          iyy="0.0108465522742051"
          iyz="4.91733251357684E-09"
          izz="0.00583602395506444" />
      </inertial>
      <visual>
        <origin
          xyz="0 0 0"
          rpy="0 0 0" />
        <geometry>
          <mesh
            filename="file://$(find urc_hw_description)/urdf/meshes/Front_Left_Wheel.STL" />
        </geometry>
        <material
          name="">
          <color
            rgba="0.792156862745098 0.819607843137255 0.933333333333333 1" />
        </material>
      </visual>
      <collision>
        <origin
          xyz="0 0 0"
          rpy="0 0 0" />
        <geometry>
          <mesh
            filename="file://$(find urc_hw_description)/urdf/meshes/Front_Left_Wheel.STL" />
        </geometry>
      </collision>
      <surface>
        <friction>
          <ode>
            <mu>${mu}</mu>
            <mu2>${mu2}</mu2>
          </ode>
        </friction>
      </surface>
    </link>
    <joint
      name="Front_Left_Shaft"
      type="continuous">
      <origin
        xyz="-0.35884 -0.36484 -0.34252"
        rpy="0 -0.0083213 -1.5708" />
      <parent
        link="Left_Leg" />
      <child
        link="Front_Left_Wheel" />
      <axis
        xyz="0 1 0" />
    </joint>
    <link
      name="Back_Left_Wheel">
      <inertial>
        <origin
          xyz="-9.85722509394549E-07 -0.0424756513980336 1.28528277876239E-06"
          rpy="0 0 0" />
        <mass
          value="1.1361661167724" />
        <inertia
          ixx="0.00583600145988187"
          ixy="-3.78130385122974E-09"
          ixz="3.44208561048418E-08"
          iyy="0.010846552274239"
          iyz="4.91663609733339E-09"
          izz="0.00583602395841195" />
      </inertial>
      <visual>
        <origin
          xyz="0 0 0"
          rpy="0 0 0" />
        <geometry>
          <mesh
            filename="file://$(find urc_hw_description)/urdf/meshes/Back_Left_Wheel.STL" />
        </geometry>
        <material
          name="">
          <color
            rgba="0.792156862745098 0.819607843137255 0.933333333333333 1" />
        </material>
      </visual>
      <collision>
        <origin
          xyz="0 0 0"
          rpy="0 0 0" />
        <geometry>
          <mesh
            filename="file://$(find urc_hw_description)/urdf/meshes/Back_Left_Wheel.STL" />
        </geometry>
      </collision>
      <surface>
        <friction>
          <ode>
            <mu>${mu}</mu>
            <mu2>${mu2}</mu2>
          </ode>
        </friction>
      </surface>
    </link>
    <joint
      name="Back_Left_Shaft"
      type="continuous">
      <origin
        xyz="-0.35884 -0.35931 0.36866"
        rpy="0 -1.3867 -1.5708" />
      <parent
        link="Left_Leg" />
      <child
        link="Back_Left_Wheel" />
      <axis
        xyz="0 1 0" />
    </joint>
    <link
      name="Differential_Bar">
      <inertial>
        <origin
          xyz="0.0001696304329344 0.0146364855896726 0.0184524262584146"
          rpy="0 0 0" />
        <mass
          value="0.35481398078544" />
        <inertia
          ixx="0.000118183325221152"
          ixy="2.50308247601608E-05"
          ixz="1.74352465550517E-08"
          iyy="0.00260829860640953"
          iyz="-8.05543749773572E-08"
          izz="0.00271714842544938" />
      </inertial>
      <visual>
        <origin
          xyz="0 0 0"
          rpy="0 0 0" />
        <geometry>
          <mesh
            filename="file://$(find urc_hw_description)/urdf/meshes/Differential_Bar.STL" />
        </geometry>
        <material
          name="">
          <color
            rgba="0.792156862745098 0.819607843137255 0.933333333333333 1" />
        </material>
      </visual>
      <collision>
        <origin
          xyz="0 0 0"
          rpy="0 0 0" />
        <geometry>
          <mesh
            filename="file://$(find urc_hw_description)/urdf/meshes/Differential_Bar.STL" />
        </geometry>
      </collision>
    </link>
    <joint
      name="Differential_Bar_Shaft"
      type="revolute">
      <origin
        xyz="0 -0.37445 -0.070294"
        rpy="1.5708 0 0" />
      <parent
        link="base_link" />
      <child
        link="Differential_Bar" />
      <axis
        xyz="0 0 1" />
      <limit
        lower="0"
        upper="0"
        effort="0"
        velocity="0" />
        <dynamics damping="0.01" friction="0.01" />
    </joint>
    <link
      name="Right_Leg">
      <inertial>
        <origin
          xyz="0.314720537608315 -0.27732042463059 0.00342777397828535"
          rpy="0 0 0" />
        <mass
          value="1.51922403384041" />
        <inertia
          ixx="0.0172747098040692"
          ixy="-1.95088285599865E-06"
          ixz="-2.76912278959164E-08"
          iyy="0.016672007901523"
          iyz="-0.000130959797312506"
          izz="0.00134369248974745" />
      </inertial>
      <visual>
        <origin
          xyz="0 0 0"
          rpy="0 0 0" />
        <geometry>
          <mesh
            filename="file://$(find urc_hw_description)/urdf/meshes/Right_Leg.STL" />
        </geometry>
        <material
          name="">
          <color
            rgba="0.792156862745098 0.819607843137255 0.933333333333333 1" />
        </material>
      </visual>
      <collision>
        <origin
          xyz="0 0 0"
          rpy="0 0 0" />
        <geometry>
          <mesh
            filename="file://$(find urc_hw_description)/urdf/meshes/Right_Leg.STL" />
        </geometry>
      </collision>
    </link>
    <joint
      name="Right_Leg_Shaft"
      type="revolute">
      <origin
        xyz="0 -0.0011403 0.0099997"
        rpy="1.5791 0 0" />
      <parent
        link="base_link" />
      <child
        link="Right_Leg" />
      <axis
        xyz="0 0 0" />
      <limit
        lower="0"
        upper="0"
        effort="0"
        velocity="0" />
        <dynamics damping="0.01" friction="0.01" />
    </joint>
    <link
      name="Front_Right_Wheel">
      <inertial>
        <origin
          xyz="-9.8607342807755E-07 -0.0424756522332874 1.28600934945489E-06"
          rpy="0 0 0" />
        <mass
          value="1.13616589675483" />
        <inertia
          ixx="0.00583600369475276"
          ixy="-3.78178980764489E-09"
          ixz="3.44207610191845E-08"
          iyy="0.0108465504538541"
          iyz="4.91693676653181E-09"
          izz="0.00583602619264686" />
      </inertial>
      <visual>
        <origin
          xyz="0 0 0"
          rpy="0 0 0" />
        <geometry>
          <mesh
            filename="file://$(find urc_hw_description)/urdf/meshes/Front_Right_Wheel.STL" />
        </geometry>
        <material
          name="">
          <color
            rgba="0.792156862745098 0.819607843137255 0.933333333333333 1" />
        </material>
      </visual>
      <collision>
        <origin
          xyz="0 0 0"
          rpy="0 0 0" />
        <geometry>
          <mesh
            filename="file://$(find urc_hw_description)/urdf/meshes/Front_Right_Wheel.STL" />
        </geometry>
      </collision>
      <surface>
        <friction>
          <ode>
            <mu>${mu}</mu>
            <mu2>${mu2}</mu2>
          </ode>
        </friction>
      </surface>
    </link>
    <joint
      name="Front_Right_Shaft"
      type="continuous">
      <origin
        xyz="0.35884 -0.37493 -0.35357"
        rpy="0 0.0083213 1.5708" />
      <parent
        link="Right_Leg" />
      <child
        link="Front_Right_Wheel" />
      <axis
        xyz="0 1 0" />
    </joint>
    <link
      name="Back_Right_Wheel">
      <inertial>
        <origin
          xyz="-9.85790539753673E-07 -0.0424756522296364 1.28556895756526E-06"
          rpy="0 0 0" />
        <mass
          value="1.13616589718668" />
        <inertia
          ixx="0.00583600369447215"
          ixy="-3.7820831107468E-09"
          ixz="3.44209450267363E-08"
          iyy="0.0108465504538551"
          iyz="4.91681588687628E-09"
          izz="0.00583602619308218" />
      </inertial>
      <visual>
        <origin
          xyz="0 0 0"
          rpy="0 0 0" />
        <geometry>
          <mesh
            filename="file://$(find urc_hw_description)/urdf/meshes/Back_Right_Wheel.STL" />
        </geometry>
        <material
          name="">
          <color
            rgba="0.792156862745098 0.819607843137255 0.933333333333333 1" />
        </material>
      </visual>
      <collision>
        <origin
          xyz="0 0 0"
          rpy="0 0 0" />
        <geometry>
          <mesh
            filename="file://$(find urc_hw_description)/urdf/meshes/Back_Right_Wheel.STL" />
        </geometry>
      </collision>
      <surface>
        <friction>
          <ode>
            <mu>${mu}</mu>
            <mu2>${mu2}</mu2>
          </ode>
        </friction>
      </surface>
    </link>
    <joint
      name="Back_Right_Shaft"
      type="continuous">
      <origin
        xyz="0.358842224999926 -0.369400178446968 0.357603754666081"
        rpy="0 0.0083213063996962 1.57079632679444" />
      <parent
        link="Right_Leg" />
      <child
        link="Back_Right_Wheel" />
      <axis
        xyz="0 1 0" />
    </joint>

    <gazebo reference="base_link">
      <material>Gazebo/Grey</material>
    </gazebo>
    <gazebo reference="Left_Leg">
      <material>Gazebo/Grey</material>
    </gazebo>
    <gazebo reference="Front_Left_Wheel">
      <material>Gazebo/Black</material>
    </gazebo>
    <gazebo reference="Back_Left_Wheel">
      <material>Gazebo/Black</material>
    </gazebo>
    <gazebo reference="Differential_Bar">
      <material>Gazebo/Grey</material>
    </gazebo>
    <gazebo reference="Right_Leg">
      <material>Gazebo/Grey</material>
    </gazebo>
    <gazebo reference="Front_Right_Wheel">
      <material>Gazebo/Black</material>
    </gazebo>
    <gazebo reference="Back_Right_Wheel">
      <material>Gazebo/Black</material>
    </gazebo>
  </xacro:macro>
</robot>
