<?xml version="1.0" encoding="UTF-8"?>
<robot name="walli" xmlns:xacro="http://ros.org/wiki/xacro">

  <!-- These includes do not work if we use the file://$(find urc_hw_description) format -->
  <!-- <xacro:include filename="$(find urc_hw_description)/urdf/walli_prop.xacro"/>
  <xacro:include filename="$(find urc_hw_description)/urdf/walli_inertials.xacro"/>
  <xacro:include filename="$(find urc_hw_description)/urdf/walli_sensors.xacro"/> -->

   <link name="base_link">
      <inertial>
         <origin xyz="-0.22771 0.0020794 0.13424" rpy="0 0 0" />
         <mass value="2.485" />
         <inertia ixx="0.017201" ixy="-2.0986E-11" ixz="5.8899E-06" iyy="0.0028906" iyz="5.0336E-07" izz="0.019124" />
      </inertial>
      <visual>
         <origin xyz="0 0 0" rpy="0 0 0" />
         <geometry>
            <mesh filename="file://$(find urc_gazebo)/urdf/meshes/visual/base_link.STL" />
         </geometry>
      </visual>
      <collision>
         <origin xyz="0 0 0" rpy="0 0 0" />
         <geometry>
            <mesh filename="file://$(find urc_gazebo)/urdf/meshes/collision/base_link_collision.STL" />
         </geometry>
      </collision>
   </link>
   <link name="rightrocker">
      <inertial>
         <origin xyz="0.062687 0.034616 -0.016048" rpy="0 0 0" />
         <mass value="0.57523" />
         <inertia ixx="0.00040232" ixy="-8.4972E-11" ixz="-0.00023706" iyy="0.00095582" iyz="-4.2951E-08" izz="0.00061776" />
      </inertial>
      <visual>
         <origin xyz="0 0 0" rpy="0 0 0" />
         <geometry>
            <mesh filename="file://$(find urc_gazebo)/urdf/meshes/visual/rightrocker.STL" />
         </geometry>
      </visual>
      <collision>
         <origin xyz="0 0 0" rpy="0 0 0" />
         <geometry>
            <mesh filename="file://$(find urc_gazebo)/urdf/meshes/collision/rightrocker_collision.STL" />
         </geometry>
      </collision>
   </link>
   <joint name="rightrockerjoint" type="fixed">
      <origin xyz="-0.194 -0.33715 0.080295" rpy="0 0 0" />
      <parent link="base_link" />
      <child link="rightrocker" />
      <axis xyz="0 0 0" />
      <dynamics damping="60" friction="4" />
   </joint>
   <link name="right_rear_wheel">
      <inertial>
         <origin xyz="0.0010497 0.10248 0.00012788" rpy="0 0 0" />
         <mass value="0.65429" />
         <inertia ixx="0.00040499" ixy="-2.9713E-08" ixz="-2.8347E-07" iyy="0.00055081" iyz="2.6154E-08" izz="0.00040532" />
      </inertial>
      <visual>
         <origin xyz="0 0 0" rpy="0 0 0" />
         <geometry>
            <mesh filename="file://$(find urc_gazebo)/urdf/meshes/visual/right_rear_wheel.STL" />
         </geometry>
      </visual>
      <collision>
         <origin xyz="0 0 0" rpy="0 0 0" />
         <geometry>
            <mesh filename="file://$(find urc_gazebo)/urdf/meshes/collision/right_rear_wheel_collision.STL" />
         </geometry>
      </collision>
   </link>
   <joint name="right_rear_wheel_joint" type="continuous">
      <origin xyz="-0.36316 -0.17103 -0.19158" rpy="0 0 0" />
      <parent link="rightrocker" />
      <child link="right_rear_wheel" />
      <axis xyz="0 -1 0" />
      <dynamics damping="4" friction="20" />
   </joint>
   <link name="rightbogie">
      <inertial>
         <origin xyz="-6.8787E-09 0.032385 -0.015429" rpy="0 0 0" />
         <mass value="0.66758" />
         <inertia ixx="0.00019756" ixy="-5.9804E-10" ixz="9.4624E-11" iyy="0.00044836" iyz="2.6509E-13" izz="0.0003846" />
      </inertial>
      <visual>
         <origin xyz="0 0 0" rpy="0 0 0" />
         <geometry>
            <mesh filename="file://$(find urc_gazebo)/urdf/meshes/visual/rightbogie.STL" />
         </geometry>
      </visual>
      <collision>
         <origin xyz="0 0 0" rpy="0 0 0" />
         <geometry>
            <mesh filename="file://$(find urc_gazebo)/urdf/meshes/collision/rightbogie_collision.STL" />
         </geometry>
      </collision>
   </link>
   <joint name="rightbogiejoint" type="fixed">
      <origin xyz="0.24177 -0.00254 -0.074203" rpy="0 0 0" />
      <parent link="rightrocker" />
      <child link="rightbogie" />
      <axis xyz="0 0 0" />
      <dynamics damping="60" friction="4" />
   </joint>
   <link name="right_front_wheel">
      <inertial>
         <origin xyz="-0.00066285 0.10248 0.00082496" rpy="0 0 0" />
         <mass value="0.65429" />
         <inertia ixx="0.000405" ixy="-2.1882E-08" ixz="2.5112E-07" iyy="0.00055081" iyz="-4.9845E-08" izz="0.00040531" />
      </inertial>
      <visual>
         <origin xyz="0 0 0" rpy="0 0 0" />
         <geometry>
            <mesh filename="file://$(find urc_gazebo)/urdf/meshes/visual/right_front_wheel.STL" />
         </geometry>
      </visual>
      <collision>
         <origin xyz="0 0 0" rpy="0 0 0" />
         <geometry>
            <mesh filename="file://$(find urc_gazebo)/urdf/meshes/collision/right_front_wheel_collision.STL" />
         </geometry>
      </collision>
   </link>
   <joint name="right_front_wheel_joint" type="continuous">
      <origin xyz="0.20139 -0.16849 -0.11671" rpy="0 0 0" />
      <parent link="rightbogie" />
      <child link="right_front_wheel" />
      <axis xyz="0 -1 0" />
      <dynamics damping="4" friction="20" />
   </joint>
   <link name="right_center_wheel">
      <inertial>
         <origin xyz="0.0010444 0.10248 0.00016665" rpy="0 0 0" />
         <mass value="0.65429" />
         <inertia ixx="0.00040501" ixy="-3.1023E-08" ixz="-2.9568E-07" iyy="0.00055081" iyz="2.5206E-08" izz="0.0004053" />
      </inertial>
      <visual>
         <origin xyz="0 0 0" rpy="0 0 0" />
         <geometry>
            <mesh filename="file://$(find urc_gazebo)/urdf/meshes/visual/right_center_wheel.STL" />
         </geometry>
      </visual>
      <collision>
         <origin xyz="0 0 0" rpy="0 0 0" />
         <geometry>
            <mesh filename="file://$(find urc_gazebo)/urdf/meshes/collision/right_center_wheel_collision.STL" />
         </geometry>
      </collision>
   </link>
   <joint name="right_center_wheel_joint" type="continuous">
      <origin xyz="-0.20177 -0.16849 -0.11606" rpy="0 0 0" />
      <parent link="rightbogie" />
      <child link="right_center_wheel" />
      <axis xyz="0 -1 0" />
      <dynamics damping="4" friction="20" />
   </joint>
   <link name="leftrocker">
      <inertial>
         <origin xyz="0.065435 -0.034981 -0.01685" rpy="0 0 0" />
         <mass value="0.58415" />
         <inertia ixx="0.0004044" ixy="-5.259E-11" ixz="-0.00023722" iyy="0.00095925" iyz="-4.2951E-08" izz="0.00061912" />
      </inertial>
      <visual>
         <origin xyz="0 0 0" rpy="0 0 0" />
         <geometry>
            <mesh filename="file://$(find urc_gazebo)/urdf/meshes/visual/leftrocker.STL" />
         </geometry>
      </visual>
      <collision>
         <origin xyz="0 0 0" rpy="0 0 0" />
         <geometry>
            <mesh filename="file://$(find urc_gazebo)/urdf/meshes/collision/leftrocker_collision.STL" />
         </geometry>
      </collision>
   </link>
   <joint name="leftrockerjoint" type="fixed">
      <origin xyz="-0.19241 0.33715 0.080257" rpy="0 0 0" />
      <parent link="base_link" />
      <child link="leftrocker" />
      <axis xyz="0 0 0" />
      <dynamics damping="60" friction="4" />
   </joint>
   <link name="left_rear_wheel">
      <inertial>
         <origin xyz="0.00069452 -0.10248 0.00079886" rpy="0 0 0" />
         <mass value="0.65433" />
         <inertia ixx="0.00040509" ixy="-4.8144E-09" ixz="-2.5925E-07" iyy="0.00055097" iyz="4.0749E-08" izz="0.00040552" />
      </inertial>
      <visual>
         <origin xyz="0 0 0" rpy="0 0 0" />
         <geometry>
            <mesh filename="file://$(find urc_gazebo)/urdf/meshes/visual/left_rear_wheel.STL" />
         </geometry>
      </visual>
      <collision>
         <origin xyz="0 0 0" rpy="0 0 0" />
         <geometry>
            <mesh filename="file://$(find urc_gazebo)/urdf/meshes/collision/left_rear_wheel_collision.STL" />
         </geometry>
      </collision>
   </link>
   <joint name="left_rear_wheel_joint" type="continuous">
      <origin xyz="-0.36266 0.17103 -0.19248" rpy="0 0 0" />
      <parent link="leftrocker" />
      <child link="left_rear_wheel" />
      <axis xyz="0 1 0" />
      <dynamics damping="4" friction="20" />
   </joint>
   <link name="leftbogie">
      <inertial>
         <origin xyz="-6.8787E-09 -0.032385 -0.015429" rpy="0 0 0" />
         <mass value="0.66758" />
         <inertia ixx="0.00019756" ixy="-5.9804E-10" ixz="9.4624E-11" iyy="0.00044836" iyz="2.6509E-13" izz="0.0003846" />
      </inertial>
      <visual>
         <origin xyz="0 0 0" rpy="0 0 0" />
         <geometry>
            <mesh filename="file://$(find urc_gazebo)/urdf/meshes/visual/leftbogie.STL" />
         </geometry>
      </visual>
      <collision>
         <origin xyz="0 0 0" rpy="0 0 0" />
         <geometry>
            <mesh filename="file://$(find urc_gazebo)/urdf/meshes/collision/leftbogie_collision.STL" />
         </geometry>
      </collision>
   </link>
   <joint name="leftbogiejoint" type="fixed">
      <origin xyz="0.24182 0.00254 -0.073984" rpy="0 0 0" />
      <parent link="leftrocker" />
      <child link="leftbogie" />
      <axis xyz="0 0 0" />
      <dynamics damping="60" friction="4" />
   </joint>
   <link name="left_front_wheel">
      <inertial>
         <origin xyz="-0.001042 -0.10248 0.00016516" rpy="0 0 0" />
         <mass value="0.65433" />
         <inertia ixx="0.00040512" ixy="-1.5424E-08" ixz="2.7516E-07" iyy="0.00055097" iyz="-3.4895E-08" izz="0.00040549" />
      </inertial>
      <visual>
         <origin xyz="0 0 0" rpy="0 0 0" />
         <geometry>
            <mesh filename="file://$(find urc_gazebo)/urdf/meshes/visual/left_front_wheel.STL" />
         </geometry>
      </visual>
      <collision>
         <origin xyz="0 0 0" rpy="0 0 0" />
         <geometry>
            <mesh filename="file://$(find urc_gazebo)/urdf/meshes/collision/left_front_wheel_collision.STL" />
         </geometry>
      </collision>
   </link>
   <joint name="left_front_wheel_joint" type="continuous">
      <origin xyz="0.20177 0.16849 -0.11606" rpy="0 0 0" />
      <parent link="leftbogie" />
      <child link="left_front_wheel" />
      <axis xyz="0 1 0" />
      <dynamics damping="4" friction="20" />
   </joint>
   <link name="left_center_wheel">
      <inertial>
         <origin xyz="0.00066514 -0.10248 0.00082348" rpy="0 0 0" />
         <mass value="0.65433" />
         <inertia ixx="0.00040511" ixy="-6.2827E-09" ixz="-2.7164E-07" iyy="0.00055097" iyz="4.0155E-08" izz="0.0004055" />
      </inertial>
      <visual>
         <origin xyz="0 0 0" rpy="0 0 0" />
         <geometry>
            <mesh filename="file://$(find urc_gazebo)/urdf/meshes/visual/left_center_wheel.STL" />
         </geometry>
      </visual>
      <collision>
         <origin xyz="0 0 0" rpy="0 0 0" />
         <geometry>
            <mesh filename="file://$(find urc_gazebo)/urdf/meshes/collision/left_center_wheel_collision.STL" />
         </geometry>
      </collision>
   </link>
   <joint name="left_center_wheel_joint" type="continuous">
      <origin xyz="-0.20139 0.16849 -0.11671" rpy="0 0 0" />
      <parent link="leftbogie" />
      <child link="left_center_wheel" />
      <axis xyz="0 1 0" />
      <dynamics damping="4" friction="20" />
   </joint>
   <link name="spine">
      <inertial>
         <origin xyz="-4.2872E-05 -0.00027225 -0.21303" rpy="0 0 0" />
         <mass value="0.9682" />
         <inertia ixx="0.01233" ixy="-4.9034E-07" ixz="-3.3052E-10" iyy="0.012329" iyz="-6.338E-06" izz="0.00039532" />
      </inertial>
      <visual>
         <origin xyz="0 0 0" rpy="0 0 0" />
         <geometry>
            <mesh filename="file://$(find urc_gazebo)/urdf/meshes/visual/spine.STL" />
         </geometry>
      </visual>
      <collision>
         <origin xyz="0 0 0" rpy="0 0 0" />
         <geometry>
            <mesh filename="file://$(find urc_gazebo)/urdf/meshes/collision/spine_collision.STL" />
         </geometry>
      </collision>
   </link>
   <joint name="spinejoint" type="fixed">
      <origin xyz="0.000513666061109697 0.00028388502121135 0.630050810000002" rpy="0 0 0" />
      <parent link="base_link" />
      <child link="spine" />
      <axis xyz="0 0 0" />
   </joint>
   <link name="shoulder">
      <inertial>
         <origin xyz="0.020518 0.053038 -0.052389" rpy="0 0 0" />
         <mass value="1.3264" />
         <inertia ixx="0.0025022" ixy="4.7083E-07" ixz="8.2027E-08" iyy="0.00092659" iyz="2.0751E-06" izz="0.0020646" />
      </inertial>
      <visual>
         <origin xyz="0 0 0" rpy="0 0 0" />
         <geometry>
            <mesh filename="file://$(find urc_gazebo)/urdf/meshes/visual/shoulder.STL" />
         </geometry>
      </visual>
      <collision>
         <origin xyz="0 0 0" rpy="0 0 0" />
         <geometry>
            <mesh filename="file://$(find urc_gazebo)/urdf/meshes/collision/shoulder_collision.STL" />
         </geometry>
      </collision>
   </link>
   <joint name="shoulderjoint" type="revolute">
      <origin xyz="0 0 0" rpy="0 0 0" />
      <parent link="spine" />
      <child link="shoulder" />
      <axis xyz="0 0 1" />
      <limit lower="-3.14" upper="3.14" effort="0" velocity="0" />
      <dynamics damping="4" friction="4" />
   </joint>
   <link name="bicep">
      <inertial>
         <origin xyz="0.12731 0.047938 0.11952" rpy="0 0 0" />
         <mass value="0.56899" />
         <inertia ixx="0.0028177" ixy="-3.8181E-18" ixz="-0.0028792" iyy="0.0058314" iyz="-3.5192E-18" izz="0.0031814" />
      </inertial>
      <visual>
         <origin xyz="0 0 0" rpy="0 0 0" />
         <geometry>
            <mesh filename="file://$(find urc_gazebo)/urdf/meshes/visual/bicep.STL" />
         </geometry>
      </visual>
      <collision>
         <origin xyz="0 0 0" rpy="0 0 0" />
         <geometry>
            <mesh filename="file://$(find urc_gazebo)/urdf/meshes/collision/bicep_collision.STL" />
         </geometry>
      </collision>
   </link>
   <joint name="bicepjoint" type="revolute">
      <origin xyz="0.046323 -0.047405 -0.052413" rpy="0 0 0" />
      <parent link="shoulder" />
      <child link="bicep" />
      <axis xyz="0 -1 0" />
      <limit lower="-3.14" upper="3.14" effort="0" velocity="0" />
      <dynamics damping="60" friction="4" />
   </joint>
   <link name="elbow">
      <inertial>
         <origin xyz="0.057399 0.088305 0.031812" rpy="0 0 0" />
         <mass value="1.7547" />
         <inertia ixx="0.0021164" ixy="2.1484E-06" ixz="-1.1917E-05" iyy="0.004637" iyz="-4.7083E-07" izz="0.0062321" />
      </inertial>
      <visual>
         <origin xyz="0 0 0" rpy="0 0 0" />
         <geometry>
            <mesh filename="file://$(find urc_gazebo)/urdf/meshes/visual/elbow.STL" />
         </geometry>
      </visual>
      <collision>
         <origin xyz="0 0 0" rpy="0 0 0" />
         <geometry>
            <mesh filename="file://$(find urc_gazebo)/urdf/meshes/collision/elbow_collision.STL" />
         </geometry>
      </collision>
   </link>
   <joint name="elbowjoint" type="revolute">
      <origin xyz="0.25459 8.2754E-05 0.23905" rpy="0 0 0" />
      <parent link="bicep" />
      <child link="elbow" />
      <axis xyz="0 -1 0" />
      <limit lower="-3.14" upper="3.14" effort="0" velocity="0" />
      <dynamics damping="60" friction="4" />
   </joint>
   <link name="wrist">
      <inertial>
         <origin xyz="-0.015666 0.09009 0.02975" rpy="0 0 0" />
         <mass value="1.641" />
         <inertia ixx="0.0020915" ixy="3.1784E-05" ixz="-5.5989E-08" iyy="0.0013998" iyz="-4.6737E-07" izz="0.0029203" />
      </inertial>
      <visual>
         <origin xyz="0 0 0" rpy="0 0 0" />
         <geometry>
            <mesh filename="file://$(find urc_gazebo)/urdf/meshes/visual/wrist.STL" />
         </geometry>
      </visual>
      <collision>
         <origin xyz="0 0 0" rpy="0 0 0" />
         <geometry>
            <mesh filename="file://$(find urc_gazebo)/urdf/meshes/collision/wrist_collision.STL" />
         </geometry>
      </collision>
   </link>
   <joint name="wristjoint" type="revolute">
      <origin xyz="0.35396 0.0035964 0.048704" rpy="0 0 0" />
      <parent link="elbow" />
      <child link="wrist" />
      <axis xyz="0 -1 0" />
      <limit lower="-3.14" upper="3.14" effort="0" velocity="0" />
      <dynamics damping="4" friction="4" />
   </joint>
   <link name="claw">
      <inertial>
         <origin xyz="-0.12039 -3.2707E-05 8.7622E-05" rpy="0 0 0" />
         <mass value="0.68517" />
         <inertia ixx="0.00085866" ixy="-3.3295E-07" ixz="3.4281E-08" iyy="0.00076618" iyz="3.4515E-08" izz="0.0015578" />
      </inertial>
      <visual>
         <origin xyz="0 0 0" rpy="0 0 0" />
         <geometry>
            <mesh filename="file://$(find urc_gazebo)/urdf/meshes/visual/claw.STL" />
         </geometry>
      </visual>
      <collision>
         <origin xyz="0 0 0" rpy="0 0 0" />
         <geometry>
            <mesh filename="file://$(find urc_gazebo)/urdf/meshes/collision/claw_collision.STL" />
         </geometry>
      </collision>
   </link>
   <joint name="clawjoint" type="revolute">
      <origin xyz="0.34674 0.047161 0.046323" rpy="0 0 0" />
      <parent link="wrist" />
      <child link="claw" />
      <axis xyz="1 0 0" />
      <limit lower="-3.14" upper="3.14" effort="0" velocity="0" />
      <dynamics damping="4" friction="4" />
   </joint>
   <link name="rightgripper">
      <inertial>
         <origin xyz="0.10255 -0.010123 -0.013053" rpy="0 0 0" />
         <mass value="0.3358" />
         <inertia ixx="0.00018107" ixy="-4.531E-05" ixz="-1.2298E-19" iyy="0.00059927" iyz="7.8324E-19" izz="0.00066862" />
      </inertial>
      <visual>
         <origin xyz="0 0 0" rpy="0 0 0" />
         <geometry>
            <mesh filename="file://$(find urc_gazebo)/urdf/meshes/visual/rightgripper.STL" />
         </geometry>
      </visual>
      <collision>
         <origin xyz="0 0 0" rpy="0 0 0" />
         <geometry>
            <mesh filename="file://$(find urc_gazebo)/urdf/meshes/collision/rightgripper_collision.STL" />
         </geometry>
      </collision>
   </link>
   <joint name="rightgripperjoint" type="revolute">
      <origin xyz="-0.030801 -0.080243 0.013053" rpy="0 0 0" />
      <parent link="claw" />
      <child link="rightgripper" />
      <axis xyz="0 0 -1" />
      <limit lower="-1.57" upper="0.6" effort="0" velocity="0" />
      <dynamics damping="4" friction="2" />
   </joint>
   <link name="leftgripper">
      <inertial>
         <origin xyz="0.10255 0.010123 -0.013053" rpy="0 0 0" />
         <mass value="0.3358" />
         <inertia ixx="0.00018107" ixy="4.531E-05" ixz="3.3128E-18" iyy="0.00059927" iyz="5.2882E-19" izz="0.00066862" />
      </inertial>
      <visual>
         <origin xyz="0 0 0" rpy="0 0 0" />
         <geometry>
            <mesh filename="file://$(find urc_gazebo)/urdf/meshes/visual/leftgripper.STL" />
         </geometry>
      </visual>
      <collision>
         <origin xyz="0 0 0" rpy="0 0 0" />
         <geometry>
            <mesh filename="file://$(find urc_gazebo)/urdf/meshes/collision/leftgripper_collision.STL" />
         </geometry>
      </collision>
   </link>
   <joint name="leftgripperjoint" type="revolute">
      <origin xyz="-0.030801 0.080243 0.013053" rpy="0 0 0" />
      <parent link="claw" />
      <child link="leftgripper" />
      <axis xyz="0 0 1" />
      <limit lower="-0.6" upper="1.57" effort="0" velocity="0" />
      <dynamics damping="4" friction="2" />
      <mimic joint="rightgripperjoint" multiplier="1" offset="0" />
   </joint>
   <gazebo reference="base_link">
      <material>Gazebo/Grey</material>
   </gazebo>
   <gazebo reference="rightrocker">
      <material>Gazebo/Grey</material>
   </gazebo>
   <gazebo reference="right_rear_wheel">
      <material>Gazebo/Black</material>
   </gazebo>
   <gazebo reference="rightbogie">
      <material>Gazebo/Grey</material>
   </gazebo>
   <gazebo reference="right_front_wheel">
      <material>Gazebo/Black</material>
   </gazebo>
   <gazebo reference="right_center_wheel">
      <material>Gazebo/Black</material>
   </gazebo>
   <gazebo reference="leftrocker">
      <material>Gazebo/Grey</material>
   </gazebo>
   <gazebo reference="left_rear_wheel">
      <material>Gazebo/Black</material>
   </gazebo>
   <gazebo reference="leftbogie">
      <material>Gazebo/Grey</material>
   </gazebo>
   <gazebo reference="left_front_wheel">
      <material>Gazebo/Black</material>
   </gazebo>
   <gazebo reference="left_center_wheel">
      <material>Gazebo/Black</material>
   </gazebo>
   <gazebo reference="spine">
      <material>Gazebo/Grey</material>
   </gazebo>
   <gazebo reference="shoulder">
      <material>Gazebo/Grey</material>
   </gazebo>
   <gazebo reference="bicep">
      <material>Gazebo/Grey</material>
   </gazebo>
   <gazebo reference="elbow">
      <material>Gazebo/Grey</material>
   </gazebo>
   <gazebo reference="wrist">
      <material>Gazebo/Grey</material>
   </gazebo>
   <gazebo reference="claw">
      <material>Gazebo/Grey</material>
   </gazebo>
   <gazebo reference="rightgripper">
      <material>Gazebo/Grey</material>
   </gazebo>
   <gazebo reference="leftgripper">
      <material>Gazebo/Grey</material>
   </gazebo>
   <gazebo reference="shoulderjoint">
      <implicitSpringDamper>true</implicitSpringDamper>
   </gazebo>
   <gazebo reference="bicepjoint">
      <implicitSpringDamper>true</implicitSpringDamper>
   </gazebo>
   <gazebo reference="elbowjoint">
      <implicitSpringDamper>true</implicitSpringDamper>
   </gazebo>
   <gazebo reference="wristjoint">
      <implicitSpringDamper>true</implicitSpringDamper>
   </gazebo>
   <gazebo reference="clawjoint">
      <implicitSpringDamper>true</implicitSpringDamper>
   </gazebo>
   <gazebo reference="leftgripperjoint">
      <implicitSpringDamper>true</implicitSpringDamper>
   </gazebo>
   <gazebo reference="rightgripperjoint">
      <implicitSpringDamper>true</implicitSpringDamper>
   </gazebo>
</robot>